Workbook

Sheet Net F
B5: =TODAY() -> 45596
B6: CUENTA 1 | C6: NOMBRE | D6: CLAVE | E6: TELEFONO | F6: PIN PERFIL | G6: precio S/ | H6: PRECIO | I6: FECHA DE INICIO | J6: DIAS | K6: FECHA DE VENCIMIENTO | L6: ALARMA | M6: ESTADO
B7: NETFLIX | C7: Vasty2193 | E7: 593 93 972 8672 | F7: 3814 | G7: $2.5 | H7: =IF(I7>0,10,0) -> 10 | I7: 45572 | J7: 30 | K7: =+'Net F'!$I7+'Net F'!$J7 -> 45602 | L7: ='Net F'!$I7+'Net F'!$J7-TODAY() -> 6 | M7: =IF(L7<1,"VENCIDO","VIGENTE") -> VIGENTE
C8: Marcelo103 | E8: 594 93 972 8672 | F8: 1138 | H8: =IF(I8>0,10,0) -> 10 | I8: 45543 | J8: 60 | K8: =+'Net F'!$I8+'Net F'!$J8 -> 45603 | L8: ='Net F'!$I8+'Net F'!$J8-TODAY() -> 7 | M8: =IF(L8<1,"VENCIDO","VIGENTE") -> VIGENTE
C9: kelly92 | E9: 51 946 140 474 | F9: 8745 | H9: =IF(I9>0,10,0) -> 10 | I9: 45524 | J9: 30 | K9: =+'Net F'!$I9+'Net F'!$J9 -> 45554 | L9: ='Net F'!$I9+'Net F'!$J9-TODAY() -> -42 | M9: =IF(L9<1,"VENCIDO","VIGENTE") -> VENCIDO
C10: alme58 | E10: 51 988 684 621 | F10: 9467 | H10: =IF(I10>0,10,0) -> 10 | I10: 45567 | J10: 30 | K10: ='Net F'!$I10+'Net F'!$J10 -> 45597 | L10: ='Net F'!$I10+'Net F'!$J10-TODAY() -> 1 | M10: =IF(L10<1,"VENCIDO","VIGENTE") -> VIGENTE
C11: Ingrid829 | E11: 51 986 430 133 | F11: 1946 | H11: =IF(I11>0,10,0) -> 10 | I11: 45554 | J11: 30 | K11: ='Net F'!$I11+'Net F'!$J11 -> 45584 | L11: ='Net F'!$I11+'Net F'!$J11-TODAY() -> -12 | M11: =IF(L11<1,"VENCIDO","VIGENTE") -> VENCIDO
C12: Moises429 | E12: 51 986 430 133 | F12: 6323 | H12: =IF(I12>0,10,0) -> 10 | I12: 45539 | J12: 30 | K12: ='Net F'!$I12+'Net F'!$J12 -> 45569 | L12: ='Net F'!$I12+'Net F'!$J12-TODAY() -> -27 | M12: =IF(L12<1,"VENCIDO","VIGENTE") -> VENCIDO
C13: Alison269 | E13: 51 924 623 553 | F13: 6659 | H13: =IF(I13>0,10,0) -> 10 | I13: 45549 | J13: 30 | K13: ='Net F'!$I13+'Net F'!$J13 -> 45579 | L13: ='Net F'!$I13+'Net F'!$J13-TODAY() -> -17 | M13: =IF(L13<1,"VENCIDO","VIGENTE") -> VENCIDO
C14: Alexander922 | E14: 51 973 042 635 | F14: 8362 | H14: =IF(I14>0,10,0) -> 10 | I14: 45563 | J14: 30 | K14: ='Net F'!$I14+'Net F'!$J14 -> 45593 | L14: ='Net F'!$I14+'Net F'!$J14-TODAY() -> -3 | M14: =IF(L14<1,"VENCIDO","VIGENTE") -> VENCIDO
C15: cathe6 | E15: 51 917 020 261 | F15: 6975 | H15: =IF(I15>0,10,0) -> 10 | I15: 45572 | J15: 30 | K15: ='Net F'!$I15+'Net F'!$J15 -> 45602 | L15: ='Net F'!$I15+'Net F'!$J15-TODAY() -> 6 | M15: =IF(L15<1,"VENCIDO","VIGENTE") -> VIGENTE
C16: clinton19 | E16: 51 965 090 265 | F16: 5827 | H16: =IF(I16>0,10,0) -> 10 | I16: 45563 | J16: 30 | K16: ='Net F'!$I16+'Net F'!$J16 -> 45593 | L16: ='Net F'!$I16+'Net F'!$J16-TODAY() -> -3 | M16: =IF(L16<1,"VENCIDO","VIGENTE") -> VENCIDO
C17: Joel2655 | E17: 51 977 840 037 | F17: 6346 | H17: =IF(I17>0,10,0) -> 10 | I17: 45557 | J17: 30 | K17: ='Net F'!$I17+'Net F'!$J17 -> 45587 | L17: ='Net F'!$I17+'Net F'!$J17-TODAY() -> -9 | M17: =IF(L17<1,"VENCIDO","VIGENTE") -> VENCIDO
C18: Jilson38 | E18: 593 98 457 2028 | F18: 6975 | H18: =IF(I18>0,10,0) -> 10 | I18: 45519 | J18: 30 | K18: ='Net F'!$I18+'Net F'!$J18 -> 45549 | L18: ='Net F'!$I18+'Net F'!$J18-TODAY() -> -47 | M18: =IF(L18<1,"VENCIDO","VIGENTE") -> VENCIDO
C19: Rihanna66 | E19: 51 970 573 661 | F19: 6289 | H19: =IF(I19>0,11,0) -> 11 | I19: 45550 | J19: 30 | K19: ='Net F'!$I19+'Net F'!$J19 -> 45580 | L19: ='Net F'!$I19+'Net F'!$J19-TODAY() -> -16 | M19: =IF(L19<1,"VENCIDO","VIGENTE") -> VENCIDO
C20: Ruth648 | E20: 51 965 090 265 | F20: 6975 | H20: =IF(I20>0,10,0) -> 10 | I20: 45506 | J20: 30 | K20: ='Net F'!$I20+'Net F'!$J20 -> 45536 | L20: ='Net F'!$I20+'Net F'!$J20-TODAY() -> -60 | M20: =IF(L20<1,"VENCIDO","VIGENTE") -> VENCIDO
C21: Jose617 | E21: 51 980 621 358 | F21: 1137 | H21: =IF(I21>0,10,0) -> 10 | I21: 45567 | J21: 30 | K21: ='Net F'!$I21+'Net F'!$J21 -> 45597 | L21: ='Net F'!$I21+'Net F'!$J21-TODAY() -> 1 | M21: =IF(L21<1,"VENCIDO","VIGENTE") -> VIGENTE
C22: Mael194 | E22: 593 96 365 3101 | F22: 6975 | H22: =IF(I22>0,10,0) -> 10 | I22: 45520 | J22: 30 | K22: ='Net F'!$I22+'Net F'!$J22 -> 45550 | L22: ='Net F'!$I22+'Net F'!$J22-TODAY() -> -46 | M22: =IF(L22<1,"VENCIDO","VIGENTE") -> VENCIDO
C23: Brider CR | E23: 51 918 845 769 | F23: 4843 | H23: =IF(I23>0,10,0) -> 10 | I23: 45573 | J23: 30 | K23: ='Net F'!$I23+'Net F'!$J23 -> 45603 | L23: ='Net F'!$I23+'Net F'!$J23-TODAY() -> 7 | M23: =IF(L23<1,"VENCIDO","VIGENTE") -> VIGENTE
C24: Guissela5 | E24: 51 994 961 537 | F24: 4844 | H24: =IF(I24>0,10,0) -> 10 | I24: 45540 | J24: 30 | K24: ='Net F'!$I24+'Net F'!$J24 -> 45570 | L24: ='Net F'!$I24+'Net F'!$J24-TODAY() -> -26 | M24: =IF(L24<1,"VENCIDO","VIGENTE") -> VENCIDO
C25: Katty428 | E25: 593 96 365 3101 | F25: 7738 | H25: =IF(I25>0,10,0) -> 10 | I25: 45512 | J25: 30 | K25: ='Net F'!$I25+'Net F'!$J25 -> 45542 | L25: ='Net F'!$I25+'Net F'!$J25-TODAY() -> -54 | M25: =IF(L25<1,"VENCIDO","VIGENTE") -> VENCIDO
C26: JONATAN142 | E26: 593 99 908 6487 | F26: 1140 | G26: $9.80 | H26: =IF(I26>0,10,0) -> 10 | I26: 45530 | J26: 30 | K26: ='Net F'!$I26+'Net F'!$J26 -> 45560 | L26: ='Net F'!$I26+'Net F'!$J26-TODAY() -> -36 | M26: =IF(L26<1,"VENCIDO","VIGENTE") -> VENCIDO
C27: Leslie18 | E27: 51 946 579 911 | F27: 6499 | H27: =IF(I27>0,10,0) -> 10 | I27: 45506 | J27: 30 | K27: ='Net F'!$I27+'Net F'!$J27 -> 45536 | L27: ='Net F'!$I27+'Net F'!$J27-TODAY() -> -60 | M27: =IF(L27<1,"VENCIDO","VIGENTE") -> VENCIDO
C28: Gina92 | E28: 51 946 579 911 | F28: 6245 | H28: =IF(I28>0,10,0) -> 10 | I28: 45570 | J28: 30 | K28: ='Net F'!$I28+'Net F'!$J28 -> 45600 | L28: ='Net F'!$I28+'Net F'!$J28-TODAY() -> 4 | M28: =IF(L28<1,"VENCIDO","VIGENTE") -> VIGENTE
C29: Criswell Ostaiza | E29: 593 96 178 8067 | F29: 4699 | H29: =IF(I29>0,10,0) -> 10 | I29: 45546 | J29: 30 | K29: ='Net F'!$I29+'Net F'!$J29 -> 45576 | L29: ='Net F'!$I29+'Net F'!$J29-TODAY() -> -20 | M29: =IF(L29<1,"VENCIDO","VIGENTE") -> VENCIDO
C30: Lyaa19 | E30: 51 917 117 242 | F30: 1827 | H30: =IF(I30>0,10,0) -> 10 | I30: 45537 | J30: 30 | K30: ='Net F'!$I30+'Net F'!$J30 -> 45567 | L30: ='Net F'!$I30+'Net F'!$J30-TODAY() -> -29 | M30: =IF(L30<1,"VENCIDO","VIGENTE") -> VENCIDO
C31: German291 | E31: 51 946 579 911 | F31: 1195 | H31: =IF(I31>0,10,0) -> 10 | I31: 45529 | J31: 30 | K31: ='Net F'!$I31+'Net F'!$J31 -> 45559 | L31: ='Net F'!$I31+'Net F'!$J31-TODAY() -> -37 | M31: =IF(L31<1,"VENCIDO","VIGENTE") -> VENCIDO
C32: Thaira185 | E32: 51 946 579 911 | F32: 7383 | H32: =IF(I32>0,10,0) -> 10 | I32: 45514 | J32: 30 | K32: ='Net F'!$I32+'Net F'!$J32 -> 45544 | L32: ='Net F'!$I32+'Net F'!$J32-TODAY() -> -52 | M32: =IF(L32<1,"VENCIDO","VIGENTE") -> VENCIDO
C33: Flavio V | E33: 51 977 364 111 | F33: 5235 | H33: =IF(I33>0,10,0) -> 10 | I33: 45535 | J33: 30 | K33: ='Net F'!$I33+'Net F'!$J33 -> 45565 | L33: ='Net F'!$I33+'Net F'!$J33-TODAY() -> -31 | M33: =IF(L33<1,"VENCIDO","VIGENTE") -> VENCIDO
C34: Miguel193 | E34: 51 917 117 242 | F34: 1936 | H34: =IF(I34>0,10,0) -> 10 | I34: 45507 | J34: 30 | K34: ='Net F'!$I34+'Net F'!$J34 -> 45537 | L34: ='Net F'!$I34+'Net F'!$J34-TODAY() -> -59 | M34: =IF(L34<1,"VENCIDO","VIGENTE") -> VENCIDO
C35: Junior139 | E35: 593 98 457 2028 | F35: 3282 | H35: =IF(I35>0,10,0) -> 10 | I35: 45543 | J35: 30 | K35: ='Net F'!$I35+'Net F'!$J35 -> 45573 | L35: ='Net F'!$I35+'Net F'!$J35-TODAY() -> -23 | M35: =IF(L35<1,"VENCIDO","VIGENTE") -> VENCIDO
C36: Emily71 | E36: 51 917 117 242 | F36: 1853 | H36: =IF(I36>0,10,0) -> 10 | I36: 45531 | J36: 30 | K36: ='Net F'!$I36+'Net F'!$J36 -> 45561 | L36: ='Net F'!$I36+'Net F'!$J36-TODAY() -> -35 | M36: =IF(L36<1,"VENCIDO","VIGENTE") -> VENCIDO
C37: justin7 | E37: 593 99 681 9196 | F37: 7458 | G37: $2.5 | H37: =IF(I37>0,10,0) -> 10 | I37: 45550 | J37: 30 | K37: ='Net F'!$I37+'Net F'!$J37 -> 45580 | L37: ='Net F'!$I37+'Net F'!$J37-TODAY() -> -16 | M37: =IF(L37<1,"VENCIDO","VIGENTE") -> VENCIDO
C38: Maximiliano52 | E38: 593 96 327 7766 | F38: 2947 | G38: $2.5 | H38: =IF(I38>0,10,0) -> 10 | I38: 45568 | J38: 30 | K38: ='Net F'!$I38+'Net F'!$J38 -> 45598 | L38: ='Net F'!$I38+'Net F'!$J38-TODAY() -> 2 | M38: =IF(L38<1,"VENCIDO","VIGENTE") -> VIGENTE
C39: Carlos Aguirre111 | E39: 593 99 624 5270 | F39: 4455 | H39: =IF(I39>0,10,0) -> 10 | I39: 45546 | J39: 30 | K39: ='Net F'!$I39+'Net F'!$J39 -> 45576 | L39: ='Net F'!$I39+'Net F'!$J39-TODAY() -> -20 | M39: =IF(L39<1,"VENCIDO","VIGENTE") -> VENCIDO
C40: Carlos Aguirre222 | E40: 593 99 624 5270 | F40: 4455 | H40: =IF(I40>0,10,0) -> 10 | I40: 45546 | J40: 30 | K40: ='Net F'!$I40+'Net F'!$J40 -> 45576 | L40: ='Net F'!$I40+'Net F'!$J40-TODAY() -> -20 | M40: =IF(L40<1,"VENCIDO","VIGENTE") -> VENCIDO
C41: Carlos Aguirre333 | E41: 593 99 624 5270 | F41: 4455 | H41: =IF(I41>0,10,0) -> 10 | I41: 45546 | J41: 30 | K41: ='Net F'!$I41+'Net F'!$J41 -> 45576 | L41: ='Net F'!$I41+'Net F'!$J41-TODAY() -> -20 | M41: =IF(L41<1,"VENCIDO","VIGENTE") -> VENCIDO
C42: Carlos Aguirre444 | E42: 593 99 624 5270 | F42: 4455 | H42: =IF(I42>0,10,0) -> 10 | I42: 45546 | J42: 30 | K42: ='Net F'!$I42+'Net F'!$J42 -> 45576 | L42: ='Net F'!$I42+'Net F'!$J42-TODAY() -> -20 | M42: =IF(L42<1,"VENCIDO","VIGENTE") -> VENCIDO
C43: Carlos Aguirre555 | E43: 593 99 624 5270 | F43: 4455 | H43: =IF(I43>0,10,0) -> 10 | I43: 45546 | J43: 30 | K43: ='Net F'!$I43+'Net F'!$J43 -> 45576 | L43: ='Net F'!$I43+'Net F'!$J43-TODAY() -> -20 | M43: =IF(L43<1,"VENCIDO","VIGENTE") -> VENCIDO
C44: Carlos Aguirre666 | E44: 593 99 624 5270 | F44: 4455 | H44: =IF(I44>0,10,0) -> 10 | I44: 45546 | J44: 30 | K44: ='Net F'!$I44+'Net F'!$J44 -> 45576 | L44: ='Net F'!$I44+'Net F'!$J44-TODAY() -> -20 | M44: =IF(L44<1,"VENCIDO","VIGENTE") -> VENCIDO
...

Sheet Net R
B6: =TODAY() -> 45596
B7: CUENTA | C7: Contraseña | D7: CLAVE | E7: Facturacion | F7: PIN PERFIL | G7: PRECIO | H7: FECHA DE INICIO | I7: DIAS | J7: FECHA DE VENCIMIENTO | K7: ALARMA | L7: ESTADO
B8: correo: byhimhas@uma3.be | C8: dek53ver4521n | G8: =IF(H8>0,30,0) -> 30 | H8: 45350 | I8: 30 | J8: =+'Net R'!$H8+'Net R'!$I8 -> 45380 | K8: ='Net R'!$H8+'Net R'!$I8-TODAY() -> -216 | L8: =IF(K8<1,"VENCIDO","VIGENTE") -> VENCIDO
G9: =IF(H9>0,30,0) -> 0 | I9: 30 | J9: =+'Net R'!$H9+'Net R'!$I9 -> 30 | K9: ='Net R'!$H9+'Net R'!$I9-TODAY() -> -45566 | L9: =IF(K9<1,"VENCIDO","VIGENTE") -> VENCIDO
G10: =IF(H10>0,30,0) -> 0 | I10: 30 | J10: =+'Net R'!$H10+'Net R'!$I10 -> 30 | K10: ='Net R'!$H10+'Net R'!$I10-TODAY() -> -45566 | L10: =IF(K10<1,"VENCIDO","VIGENTE") -> VENCIDO
G11: =IF(H11>0,30,0) -> 0 | I11: 30 | J11: =+'Net R'!$H11+'Net R'!$I11 -> 30 | K11: ='Net R'!$H11+'Net R'!$I11-TODAY() -> -45566 | L11: =IF(K11<1,"VENCIDO","VIGENTE") -> VENCIDO
G12: =IF(H12>0,30,0) -> 0 | I12: 30 | J12: =+'Net R'!$H12+'Net R'!$I12 -> 30 | K12: ='Net R'!$H12+'Net R'!$I12-TODAY() -> -45566 | L12: =IF(K12<1,"VENCIDO","VIGENTE") -> VENCIDO
G13: =IF(H13>0,30,0) -> 0 | I13: 30 | J13: =+'Net R'!$H13+'Net R'!$I13 -> 30 | K13: ='Net R'!$H13+'Net R'!$I13-TODAY() -> -45566 | L13: =IF(K13<1,"VENCIDO","VIGENTE") -> VENCIDO
G14: =IF(H14>0,30,0) -> 0 | I14: 30 | J14: =+'Net R'!$H14+'Net R'!$I14 -> 30 | K14: ='Net R'!$H14+'Net R'!$I14-TODAY() -> -45566 | L14: =IF(K14<1,"VENCIDO","VIGENTE") -> VENCIDO
G15: =IF(H15>0,30,0) -> 0 | I15: 30 | J15: =+'Net R'!$H15+'Net R'!$I15 -> 30 | K15: ='Net R'!$H15+'Net R'!$I15-TODAY() -> -45566 | L15: =IF(K15<1,"VENCIDO","VIGENTE") -> VENCIDO
G16: =IF(H16>0,30,0) -> 0 | I16: 30 | J16: =+'Net R'!$H16+'Net R'!$I16 -> 30 | K16: ='Net R'!$H16+'Net R'!$I16-TODAY() -> -45566 | L16: =IF(K16<1,"VENCIDO","VIGENTE") -> VENCIDO
G17: =IF(H17>0,30,0) -> 0 | I17: 30 | J17: =+'Net R'!$H17+'Net R'!$I17 -> 30 | K17: ='Net R'!$H17+'Net R'!$I17-TODAY() -> -45566 | L17: =IF(K17<1,"VENCIDO","VIGENTE") -> VENCIDO
G18: =IF(H18>0,30,0) -> 0 | I18: 30 | J18: =+'Net R'!$H18+'Net R'!$I18 -> 30 | K18: ='Net R'!$H18+'Net R'!$I18-TODAY() -> -45566 | L18: =IF(K18<1,"VENCIDO","VIGENTE") -> VENCIDO
G19: =IF(H19>0,30,0) -> 0 | I19: 30 | J19: =+'Net R'!$H19+'Net R'!$I19 -> 30 | K19: ='Net R'!$H19+'Net R'!$I19-TODAY() -> -45566 | L19: =IF(K19<1,"VENCIDO","VIGENTE") -> VENCIDO
G20: =IF(H20>0,30,0) -> 0 | I20: 30 | J20: =+'Net R'!$H20+'Net R'!$I20 -> 30 | K20: ='Net R'!$H20+'Net R'!$I20-TODAY() -> -45566 | L20: =IF(K20<1,"VENCIDO","VIGENTE") -> VENCIDO
G21: =SUM(G8:G20) -> 30
B26: Cuentas Disney
B27: =TODAY() -> 45596
B28: CUENTA | C28: Contraseña | D28: CLAVE | E28: Facturacion | F28: PIN PERFIL | G28: PRECIO | H28: FECHA DE INICIO | I28: DIAS | J28: FECHA DE VENCIMIENTO | K28: ALARMA | L28: ESTADO
G29: =IF(H29>0,30,0) -> 0 | I29: 30 | J29: =+'Net R'!$H29+'Net R'!$I29 -> 30 | K29: ='Net R'!$H29+'Net R'!$I29-TODAY() -> -45566 | L29: =IF(K29<1,"VENCIDO","VIGENTE") -> VENCIDO
G30: =IF(H30>0,30,0) -> 0 | I30: 30 | J30: =+'Net R'!$H30+'Net R'!$I30 -> 30 | K30: ='Net R'!$H30+'Net R'!$I30-TODAY() -> -45566 | L30: =IF(K30<1,"VENCIDO","VIGENTE") -> VENCIDO
G31: =IF(H31>0,30,0) -> 0 | I31: 30 | J31: =+'Net R'!$H31+'Net R'!$I31 -> 30 | K31: ='Net R'!$H31+'Net R'!$I31-TODAY() -> -45566 | L31: =IF(K31<1,"VENCIDO","VIGENTE") -> VENCIDO
G32: =IF(H32>0,30,0) -> 0 | I32: 30 | J32: =+'Net R'!$H32+'Net R'!$I32 -> 30 | K32: ='Net R'!$H32+'Net R'!$I32-TODAY() -> -45566 | L32: =IF(K32<1,"VENCIDO","VIGENTE") -> VENCIDO
G33: =IF(H33>0,30,0) -> 0 | I33: 30 | J33: =+'Net R'!$H33+'Net R'!$I33 -> 30 | K33: ='Net R'!$H33+'Net R'!$I33-TODAY() -> -45566 | L33: =IF(K33<1,"VENCIDO","VIGENTE") -> VENCIDO
G34: =IF(H34>0,30,0) -> 0 | I34: 30 | J34: =+'Net R'!$H34+'Net R'!$I34 -> 30 | K34: ='Net R'!$H34+'Net R'!$I34-TODAY() -> -45566 | L34: =IF(K34<1,"VENCIDO","VIGENTE") -> VENCIDO
G35: =IF(H35>0,30,0) -> 0 | I35: 30 | J35: =+'Net R'!$H35+'Net R'!$I35 -> 30 | K35: ='Net R'!$H35+'Net R'!$I35-TODAY() -> -45566 | L35: =IF(K35<1,"VENCIDO","VIGENTE") -> VENCIDO
G36: =IF(H36>0,30,0) -> 0 | I36: 30 | J36: =+'Net R'!$H36+'Net R'!$I36 -> 30 | K36: ='Net R'!$H36+'Net R'!$I36-TODAY() -> -45566 | L36: =IF(K36<1,"VENCIDO","VIGENTE") -> VENCIDO
G37: =IF(H37>0,30,0) -> 0 | I37: 30 | J37: =+'Net R'!$H37+'Net R'!$I37 -> 30 | K37: ='Net R'!$H37+'Net R'!$I37-TODAY() -> -45566 | L37: =IF(K37<1,"VENCIDO","VIGENTE") -> VENCIDO
G38: =IF(H38>0,30,0) -> 0 | I38: 30 | J38: =+'Net R'!$H38+'Net R'!$I38 -> 30 | K38: ='Net R'!$H38+'Net R'!$I38-TODAY() -> -45566 | L38: =IF(K38<1,"VENCIDO","VIGENTE") -> VENCIDO
G39: =IF(H39>0,30,0) -> 0 | I39: 30 | J39: =+'Net R'!$H39+'Net R'!$I39 -> 30 | K39: ='Net R'!$H39+'Net R'!$I39-TODAY() -> -45566 | L39: =IF(K39<1,"VENCIDO","VIGENTE") -> VENCIDO
G40: =IF(H40>0,30,0) -> 0 | I40: 30 | J40: =+'Net R'!$H40+'Net R'!$I40 -> 30 | K40: ='Net R'!$H40+'Net R'!$I40-TODAY() -> -45566 | L40: =IF(K40<1,"VENCIDO","VIGENTE") -> VENCIDO
G41: =IF(H41>0,30,0) -> 0 | I41: 30 | J41: =+'Net R'!$H41+'Net R'!$I41 -> 30 | K41: ='Net R'!$H41+'Net R'!$I41-TODAY() -> -45566 | L41: =IF(K41<1,"VENCIDO","VIGENTE") -> VENCIDO
G42: =SUM(G29:G41) -> 0
B48: =TODAY() -> 45596
B49: CUENTA | C49: Contraseña | D49: CLAVE | E49: Facturacion | F49: PIN PERFIL | G49: PRECIO | H49: FECHA DE INICIO | I49: DIAS | J49: FECHA DE VENCIMIENTO | K49: ALARMA | L49: ESTADO
G50: =IF(H50>0,30,0) -> 0 | I50: 30 | J50: =+'Net R'!$H50+'Net R'!$I50 -> 30 | K50: ='Net R'!$H50+'Net R'!$I50-TODAY() -> -45566 | L50: =IF(K50<1,"VENCIDO","VIGENTE") -> VENCIDO
G51: =IF(H51>0,30,0) -> 0 | I51: 30 | J51: =+'Net R'!$H51+'Net R'!$I51 -> 30 | K51: ='Net R'!$H51+'Net R'!$I51-TODAY() -> -45566 | L51: =IF(K51<1,"VENCIDO","VIGENTE") -> VENCIDO
G52: =IF(H52>0,30,0) -> 0 | I52: 30 | J52: =+'Net R'!$H52+'Net R'!$I52 -> 30 | K52: ='Net R'!$H52+'Net R'!$I52-TODAY() -> -45566 | L52: =IF(K52<1,"VENCIDO","VIGENTE") -> VENCIDO
G53: =IF(H53>0,30,0) -> 0 | I53: 30 | J53: =+'Net R'!$H53+'Net R'!$I53 -> 30 | K53: ='Net R'!$H53+'Net R'!$I53-TODAY() -> -45566 | L53: =IF(K53<1,"VENCIDO","VIGENTE") -> VENCIDO
G54: =IF(H54>0,30,0) -> 0 | I54: 30 | J54: =+'Net R'!$H54+'Net R'!$I54 -> 30 | K54: ='Net R'!$H54+'Net R'!$I54-TODAY() -> -45566 | L54: =IF(K54<1,"VENCIDO","VIGENTE") -> VENCIDO
...

Sheet star F (2)
B5: ALERTA DIAS
B6: =TODAY() -> 45596
B7: CUENTA 1 | C7: NOMBRE | D7: CLAVE | E7: TELEFONO | F7: PIN PERFIL | G7: PRECIO | H7: FECHA DE INICIO | I7: DIAS | J7: FECHA DE VENCIMIENTO | K7: ALARMA | L7: ESTADO
B8: CORREO: guert2303dek@gmail.com CONTRASEÑA: de334me213 | C8: Cristhian933 | F8: 1876 | G8: 3.5 | H8: 45360 | I8: 30 | J8: =CORREOSnetflix!J4 -> 45608 | K8: ='star F (2)'!$H8+'star F (2)'!$I8-TODAY() -> -206 | L8: =IF(K8<1,"VENCIDO","VIGENTE") -> VENCIDO
C9: guillermo354 | F9: 5056 | G9: 3.5 | H9: 45346 | I9: 30 | J9: =+'star F (2)'!$H9+'star F (2)'!$I9 -> 45376 | K9: ='star F (2)'!$H9+'star F (2)'!$I9-TODAY() -> -220 | L9: =IF(K9<1,"VENCIDO","VIGENTE") -> VENCIDO
C10: josue245 | F10: 5058 | G10: 3.5 | H10: 45351 | I10: 30 | J10: =+'star F (2)'!$H10+'star F (2)'!$I10 -> 45381 | K10: ='star F (2)'!$H10+'star F (2)'!$I10-TODAY() -> -215 | L10: =IF(K10<1,"VENCIDO","VIGENTE") -> VENCIDO
C11: Luis61 | F11: 2748 | G11: 3.5 | H11: 45354 | I11: 30 | J11: =+'star F (2)'!$H11+'star F (2)'!$I11 -> 45384 | K11: ='star F (2)'!$H11+'star F (2)'!$I11-TODAY() -> -212 | L11: =IF(K11<1,"VENCIDO","VIGENTE") -> VENCIDO
C12: Luis732 | F12: 4699 | G12: 3.5 | H12: 45360 | I12: 30 | J12: =+'star F (2)'!$H12+'star F (2)'!$I12 -> 45390 | K12: ='star F (2)'!$H12+'star F (2)'!$I12-TODAY() -> -206 | L12: =IF(K12<1,"VENCIDO","VIGENTE") -> VENCIDO
C13: MAyreli64 | F13: 5103 | G13: 3.5 | H13: 45350 | I13: 30 | J13: =+'star F (2)'!$H13+'star F (2)'!$I13 -> 45380 | K13: ='star F (2)'!$H13+'star F (2)'!$I13-TODAY() -> -216 | L13: =IF(K13<1,"VENCIDO","VIGENTE") -> VENCIDO
C14: rosmery64 | G14: =IF(H14>0,7,0) -> 7 | H14: 45350 | I14: 30 | J14: =+'star F (2)'!$H14+'star F (2)'!$I14 -> 45380 | K14: ='star F (2)'!$H14+'star F (2)'!$I14-TODAY() -> -216 | L14: =IF(K14<1,"VENCIDO","VIGENTE") -> VENCIDO
C15: PERFILES : | F15: =SUM(F8:F14) -> 24540 | G15: =SUM(G8:G14) -> 28 | I15: 30 | J15: =+'star F (2)'!$H15+'star F (2)'!$I15 -> 30 | K15: ='star F (2)'!$H15+'star F (2)'!$I15-TODAY() -> -45566
B22: ALERTA DIAS
B23: =TODAY() -> 45596
B24: CUENTA | C24: NOMBRE | D24: CLAVE | E24: TELEFONO | F24: PIN PERFIL | G24: PRECIO | H24: FECHA DE INICIO | I24: DIAS | J24: FECHA DE VENCIMIENTO | K24: ALARMA | L24: ESTADO
B25: CORREO : lunigu332dek@gmail.com CONTRASEÑA: verde75144 | F25: 4268 | G25: 3.5 | I25: 30 | J25: =+'star F (2)'!$H25+'star F (2)'!$I25 -> 30 | K25: ='star F (2)'!$H25+'star F (2)'!$I25-TODAY() -> -45566 | L25: =IF(K25<1,"VENCIDO","VIGENTE") -> VENCIDO
F26: 4068 | G26: 3.5 | I26: 30 | J26: =+'star F (2)'!$H26+'star F (2)'!$I26 -> 30 | K26: ='star F (2)'!$H26+'star F (2)'!$I26-TODAY() -> -45566 | L26: =IF(K26<1,"VENCIDO","VIGENTE") -> VENCIDO
C27: emanuel7 | F27: 4728 | G27: 3.5 | H27: 45251 | I27: 30 | J27: =+'star F (2)'!$H27+'star F (2)'!$I27 -> 45281 | K27: ='star F (2)'!$H27+'star F (2)'!$I27-TODAY() -> -315 | L27: =IF(K27<1,"VENCIDO","VIGENTE") -> VENCIDO
C28: jesus | F28: 4545 | G28: 3.5 | H28: 45241 | I28: 30 | J28: =+'star F (2)'!$H28+'star F (2)'!$I28 -> 45271 | K28: ='star F (2)'!$H28+'star F (2)'!$I28-TODAY() -> -325 | L28: =IF(K28<1,"VENCIDO","VIGENTE") -> VENCIDO
F29: 7474 | G29: 3.5 | I29: 30 | J29: =+'star F (2)'!$H29+'star F (2)'!$I29 -> 30 | K29: ='star F (2)'!$H29+'star F (2)'!$I29-TODAY() -> -45566 | L29: =IF(K29<1,"VENCIDO","VIGENTE") -> VENCIDO
C30: miguel | F30: 4545 | G30: 3.5 | H30: 45234 | I30: 30 | J30: =+'star F (2)'!$H30+'star F (2)'!$I30 -> 45264 | K30: ='star F (2)'!$H30+'star F (2)'!$I30-TODAY() -> -332 | L30: =IF(K30<1,"VENCIDO","VIGENTE") -> VENCIDO
G31: =IF(H31>0,7,0) -> 0 | I31: 30 | J31: =+'star F (2)'!$H31+'star F (2)'!$I31 -> 30 | K31: ='star F (2)'!$H31+'star F (2)'!$I31-TODAY() -> -45566 | L31: =IF(K31<1,"VENCIDO","VIGENTE") -> VENCIDO
C32: PERFILES : | F32: =SUM(F25:F31) -> 29628 | G32: =SUM(G25:G31) -> 21 | I32: 30 | J32: =+'star F (2)'!$H32+'star F (2)'!$I32 -> 30 | K32: ='star F (2)'!$H32+'star F (2)'!$I32-TODAY() -> -45566
B39: ALERTA DIAS
B40: =TODAY() -> 45596
B41: CUENTA | C41: NOMBRE | D41: CLAVE | E41: TELEFONO | F41: PIN PERFIL | G41: PRECIO | H41: FECHA DE INICIO | I41: DIAS | J41: FECHA DE VENCIMIENTO | K41: ALARMA | L41: ESTADO
B42: CORREO : lunigu332dek@gmail.com CONTRASEÑA: verde75144 | C42: Joan | F42: 6548 | G42: 3.5 | H42: 45239 | I42: 30 | J42: =+'star F (2)'!$H42+'star F (2)'!$I42 -> 45269 | K42: ='star F (2)'!$H42+'star F (2)'!$I42-TODAY() -> -327 | L42: =IF(K42<1,"VENCIDO","VIGENTE") -> VENCIDO
C43: ana | F43: 3696 | G43: 3.5 | H43: 45248 | I43: 30 | J43: =+'star F (2)'!$H43+'star F (2)'!$I43 -> 45278 | K43: ='star F (2)'!$H43+'star F (2)'!$I43-TODAY() -> -318 | L43: =IF(K43<1,"VENCIDO","VIGENTE") -> VENCIDO
C44: mari | F44: 3712 | G44: 3.5 | H44: 45235 | I44: 30 | J44: =+'star F (2)'!$H44+'star F (2)'!$I44 -> 45265 | K44: ='star F (2)'!$H44+'star F (2)'!$I44-TODAY() -> -331 | L44: =IF(K44<1,"VENCIDO","VIGENTE") -> VENCIDO
G45: 3.5 | I45: 30 | J45: =+'star F (2)'!$H45+'star F (2)'!$I45 -> 30 | K45: ='star F (2)'!$H45+'star F (2)'!$I45-TODAY() -> -45566 | L45: =IF(K45<1,"VENCIDO","VIGENTE") -> VENCIDO
C46: moises | F46: 6323 | G46: 3.5 | H46: 45233 | I46: 30 | J46: =+'star F (2)'!$H46+'star F (2)'!$I46 -> 45263 | K46: ='star F (2)'!$H46+'star F (2)'!$I46-TODAY() -> -333 | L46: =IF(K46<1,"VENCIDO","VIGENTE") -> VENCIDO
G47: 3.5 | I47: 30 | J47: =+'star F (2)'!$H47+'star F (2)'!$I47 -> 30 | K47: ='star F (2)'!$H47+'star F (2)'!$I47-TODAY() -> -45566 | L47: =IF(K47<1,"VENCIDO","VIGENTE") -> VENCIDO
G48: 3.5 | I48: 30 | J48: =+'star F (2)'!$H48+'star F (2)'!$I48 -> 30 | K48: ='star F (2)'!$H48+'star F (2)'!$I48-TODAY() -> -45566 | L48: =IF(K48<1,"VENCIDO","VIGENTE") -> VENCIDO
C49: PERFILES : | F49: =SUM(F42:F48) -> 20279 | G49: =SUM(G42:G48) -> 24.5 | I49: 30 | J49: =+'star F (2)'!$H49+'star F (2)'!$I49 -> 30 | K49: ='star F (2)'!$H49+'star F (2)'!$I49-TODAY() -> -45566
B57: ALERTA DIAS
B58: =TODAY() -> 45596
B59: CUENTA | C59: NOMBRE | D59: CLAVE | E59: TELEFONO | F59: PIN PERFIL | G59: PRECIO | H59: FECHA DE INICIO | I59: DIAS | J59: FECHA DE VENCIMIENTO | K59: ALARMA | L59: ESTADO
B60: Correo : deku75490stream@gmail.com Contraseña : dek457n64ge | C60: iris9 | G60: =IF(H60>0,7,0) -> 7 | H60: 45242 | I60: 30 | J60: =+'star F (2)'!$H60+'star F (2)'!$I60 -> 45272 | K60: ='star F (2)'!$H60+'star F (2)'!$I60-TODAY() -> -324 | L60: =IF(K60<1,"VENCIDO","VIGENTE") -> VENCIDO
C61: david7 | F61: 6017 | G61: =IF(H61>0,7,0) -> 7 | H61: 45245 | I61: 30 | J61: =+'star F (2)'!$H61+'star F (2)'!$I61 -> 45275 | K61: ='star F (2)'!$H61+'star F (2)'!$I61-TODAY() -> -321 | L61: =IF(K61<1,"VENCIDO","VIGENTE") -> VENCIDO
C62: gabo16 | G62: =IF(H62>0,7,0) -> 7 | H62: 45260 | I62: 30 | J62: =+'star F (2)'!$H62+'star F (2)'!$I62 -> 45290 | K62: ='star F (2)'!$H62+'star F (2)'!$I62-TODAY() -> -306 | L62: =IF(K62<1,"VENCIDO","VIGENTE") -> VENCIDO
C63: gabo18 | G63: =IF(H63>0,7,0) -> 7 | H63: 45260 | I63: 30 | J63: =+'star F (2)'!$H63+'star F (2)'!$I63 -> 45290 | K63: ='star F (2)'!$H63+'star F (2)'!$I63-TODAY() -> -306 | L63: =IF(K63<1,"VENCIDO","VIGENTE") -> VENCIDO
...

Sheet CORREOSnetflix
A1: ALERTA DIAS
A2: =TODAY() -> 45596
A3: CUENTA | B3: NOMBRE | C3: CLAVE | D3: TELEFONO | E3: PIN PERFIL | F3: PRECIO US | G3: PRECIO | H3: FECHA DE INICIO | I3: DIAS | J3: FECHA DE VENCIMIENTO | K3: ALARMA | L3: ESTADO
A4: Correo : real945@lowxvr.com Contraseña : frio923 | B4: Angel63 | D4: +51 946 579 911 | E4: 2548 | G4: 10 | H4: 45578 | I4: 30 | J4: =+Table_714[[#This Row],[FECHA DE INICIO]]+Table_714[[#This Row],[DIAS]] -> 45608 | K4: =+Table_714[[#This Row],[FECHA DE INICIO]]+Table_714[[#This Row],[DIAS]]-TODAY() -> 12 | L4: =IF(K4<1,"VENCIDO","VIGENTE") -> VIGENTE
B5: xiomara433 | D5: 51 946 579 911 | E5: 8225 | G5: 10 | H5: 45565 | I5: 30 | J5: =+Table_714[[#This Row],[FECHA DE INICIO]]+Table_714[[#This Row],[DIAS]] -> 45595 | K5: =+Table_714[[#This Row],[FECHA DE INICIO]]+Table_714[[#This Row],[DIAS]]-TODAY() -> -1 | L5: =IF(K5<1,"VENCIDO","VIGENTE") -> VENCIDO
B6: Dannis peña3 | D6: 51 994 876 608 | E6: 9458 | G6: 10 | H6: 45580 | I6: 30 | J6: =+Table_714[[#This Row],[FECHA DE INICIO]]+Table_714[[#This Row],[DIAS]] -> 45610 | K6: =+Table_714[[#This Row],[FECHA DE INICIO]]+Table_714[[#This Row],[DIAS]]-TODAY() -> 14 | L6: =IF(K6<1,"VENCIDO","VIGENTE") -> VIGENTE
B7: Stward17 | D7: 593 96 365 3101 | E7: 3323 | F7: $2.5 | H7: 45582 | I7: 30 | J7: =+Table_714[[#This Row],[FECHA DE INICIO]]+Table_714[[#This Row],[DIAS]] -> 45612 | K7: =+Table_714[[#This Row],[FECHA DE INICIO]]+Table_714[[#This Row],[DIAS]]-TODAY() -> 16 | L7: =IF(K7<1,"VENCIDO","VIGENTE") -> VIGENTE
B8: Tania Silva924 | D8: 51921561639 | E8: 2736 | G8: 10 | H8: 45585 | I8: 30 | J8: =+Table_714[[#This Row],[FECHA DE INICIO]]+Table_714[[#This Row],[DIAS]] -> 45615 | K8: =+Table_714[[#This Row],[FECHA DE INICIO]]+Table_714[[#This Row],[DIAS]]-TODAY() -> 19 | L8: =IF(K8<1,"VENCIDO","VIGENTE") -> VIGENTE
B9: PERFILES : | E9: =SUM(E4:E8) -> 26290 | G9: =SUM(G4:G8) -> 40 | I9: 30 | J9: =+'star F (2)'!$H11+'star F (2)'!$I11 -> 45384 | K9: ='star F (2)'!$H11+'star F (2)'!$I11-TODAY() -> -212
A12: ALERTA DIAS
A13: =TODAY() -> 45596
A14: CUENTA | B14: NOMBRE | C14: CLAVE | D14: TELEFONO | E14: PIN PERFIL | F14: PRECIO US | G14: PRECIO | H14: FECHA DE INICIO | I14: DIAS | J14: FECHA DE VENCIMIENTO | K14: ALARMA | L14: ESTADO
A15: correo: cien678@lowxvr.com Contraseña: fast654 | B15: Jhessi144 | D15: +51 946 579 911 | E15: 1444 | G15: 10 | H15: 45565 | I15: 30 | J15: =+Table_7145[[#This Row],[FECHA DE INICIO]]+Table_7145[[#This Row],[DIAS]] -> 45595 | K15: =+Table_7145[[#This Row],[FECHA DE INICIO]]+Table_7145[[#This Row],[DIAS]]-TODAY() -> -1 | L15: =IF(K15<1,"VENCIDO","VIGENTE") -> VENCIDO
B16: Nancita93 | E16: 9373 | I16: 30 | J16: =+Table_7145[[#This Row],[FECHA DE INICIO]]+Table_7145[[#This Row],[DIAS]] -> 30 | K16: =+Table_7145[[#This Row],[FECHA DE INICIO]]+Table_7145[[#This Row],[DIAS]]-TODAY() -> -45566 | L16: =IF(K16<1,"VENCIDO","VIGENTE") -> VENCIDO
B17: Jadiel992 | D17: +51 965 090 265 | E17: 1152 | G17: 9 | H17: 45575 | I17: 30 | J17: =+Table_7145[[#This Row],[FECHA DE INICIO]]+Table_7145[[#This Row],[DIAS]] -> 45605 | K17: =+Table_7145[[#This Row],[FECHA DE INICIO]]+Table_7145[[#This Row],[DIAS]]-TODAY() -> 9 | L17: =IF(K17<1,"VENCIDO","VIGENTE") -> VIGENTE
B18: Moises429 | D18: +51 986 430 133 | E18: 6323 | G18: 10 | H18: 45570 | I18: 30 | J18: =+Table_7145[[#This Row],[FECHA DE INICIO]]+Table_7145[[#This Row],[DIAS]] -> 45600 | K18: =+Table_7145[[#This Row],[FECHA DE INICIO]]+Table_7145[[#This Row],[DIAS]]-TODAY() -> 4 | L18: =IF(K18<1,"VENCIDO","VIGENTE") -> VIGENTE
B19: Cathe6 | D19: 51 917 020 261 | E19: 3468 | G19: 10 | H19: 45572 | I19: 30 | J19: =+Table_7145[[#This Row],[FECHA DE INICIO]]+Table_7145[[#This Row],[DIAS]] -> 45602 | K19: =+Table_7145[[#This Row],[FECHA DE INICIO]]+Table_7145[[#This Row],[DIAS]]-TODAY() -> 6 | L19: =IF(K19<1,"VENCIDO","VIGENTE") -> VIGENTE
B20: PERFILES : | E20: =SUM(E15:E19) -> 21760 | G20: =SUM(G15:G19) -> 39 | I20: 30 | J20: =+'star F (2)'!$H23+'star F (2)'!$I23 -> 0 | K20: ='star F (2)'!$H23+'star F (2)'!$I23-TODAY() -> -45596
A29: ALERTA DIAS
A30: =TODAY() -> 45596
A31: CUENTA | B31: NOMBRE | C31: CLAVE | D31: TELEFONO | E31: PIN PERFIL | F31: PRECIO US | G31: PRECIO | H31: FECHA DE INICIO | I31: DIAS | J31: FECHA DE VENCIMIENTO | K31: ALARMA | L31: ESTADO
A32: correo:prem139@lowcute.com contraseña:de16ku46ver | B32: Rose926 | D32: 51 963 728 882 | E32: 1292 | G32: 10 | H32: 45550 | I32: 30 | J32: =+Table_71457[[#This Row],[FECHA DE INICIO]]+Table_71457[[#This Row],[DIAS]] -> 45580 | K32: =+Table_71457[[#This Row],[FECHA DE INICIO]]+Table_71457[[#This Row],[DIAS]]-TODAY() -> -16 | L32: =IF(K32<1,"VENCIDO","VIGENTE") -> VENCIDO
B33: Abraham Obregón | D33: 51 942 257 254 | E33: 3467 | G33: 10 | H33: 45583 | I33: 30 | J33: =+Table_71457[[#This Row],[FECHA DE INICIO]]+Table_71457[[#This Row],[DIAS]] -> 45613 | K33: =+Table_71457[[#This Row],[FECHA DE INICIO]]+Table_71457[[#This Row],[DIAS]]-TODAY() -> 17 | L33: =IF(K33<1,"VENCIDO","VIGENTE") -> VIGENTE
B34: Sr:jp | D34: 593 98 484 3636 | E34: 1583 | F34: $2.5 | H34: 45596 | I34: 30 | J34: =+Table_71457[[#This Row],[FECHA DE INICIO]]+Table_71457[[#This Row],[DIAS]] -> 45626 | K34: =+Table_71457[[#This Row],[FECHA DE INICIO]]+Table_71457[[#This Row],[DIAS]]-TODAY() -> 30 | L34: =IF(K34<1,"VENCIDO","VIGENTE") -> VIGENTE
B35: Vasty2193 | D35: 593 93 972 8672 | E35: 3823 | F35: 2.5 | H35: 45572 | I35: 30 | J35: =+Table_71457[[#This Row],[FECHA DE INICIO]]+Table_71457[[#This Row],[DIAS]] -> 45602 | K35: =+Table_71457[[#This Row],[FECHA DE INICIO]]+Table_71457[[#This Row],[DIAS]]-TODAY() -> 6 | L35: =IF(K35<1,"VENCIDO","VIGENTE") -> VIGENTE
B36: Nicol399 | D36: 51 946 579 911 | E36: 1566 | G36: 10 | H36: 45578 | I36: 30 | J36: =+Table_71457[[#This Row],[FECHA DE INICIO]]+Table_71457[[#This Row],[DIAS]] -> 45608 | K36: =+Table_71457[[#This Row],[FECHA DE INICIO]]+Table_71457[[#This Row],[DIAS]]-TODAY() -> 12 | L36: =IF(K36<1,"VENCIDO","VIGENTE") -> VIGENTE
B37: PERFILES : | E37: =SUM(E32:E36) -> 11731 | G37: =SUM(G32:G36) -> 30 | I37: 30 | J37: =+'star F (2)'!$H40+'star F (2)'!$I40 -> 0 | K37: ='star F (2)'!$H40+'star F (2)'!$I40-TODAY() -> -45596
D43: jerik nose fecha de pago
A44: ALERTA DIAS
A45: =TODAY() -> 45596
A46: CUENTA | B46: NOMBRE | C46: CLAVE | D46: TELEFONO | E46: PIN PERFIL | F46: PRECIO US | G46: PRECIO | H46: FECHA DE INICIO | I46: DIAS | J46: FECHA DE VENCIMIENTO | K46: ALARMA | L46: ESTADO
A47: Correo : atjuggod@stayhome.li Contraseña: deke73ku82 | B47: Marcelo103 | E47: 1138 | F47: $5 | H47: 45542 | I47: 60 | J47: =+Table_714578[[#This Row],[FECHA DE INICIO]]+Table_714578[[#This Row],[DIAS]] -> 45602 | K47: =+Table_714578[[#This Row],[FECHA DE INICIO]]+Table_714578[[#This Row],[DIAS]]-TODAY() -> 6 | L47: =IF(K47<1,"VENCIDO","VIGENTE") -> VIGENTE
B48: Lyaa19 | D48: +51 917 117 242 | E48: 1827 | G48: 8 | H48: 45538 | I48: 30 | J48: =+Table_714578[[#This Row],[FECHA DE INICIO]]+Table_714578[[#This Row],[DIAS]] -> 45568 | K48: =+Table_714578[[#This Row],[FECHA DE INICIO]]+Table_714578[[#This Row],[DIAS]]-TODAY() -> -28 | L48: =IF(K48<1,"VENCIDO","VIGENTE") -> VENCIDO
B49: Yulissa184 | D49: +593 95 900 1567 | E49: 2946 | I49: 30 | J49: =+Table_714578[[#This Row],[FECHA DE INICIO]]+Table_714578[[#This Row],[DIAS]] -> 30 | K49: =+Table_714578[[#This Row],[FECHA DE INICIO]]+Table_714578[[#This Row],[DIAS]]-TODAY() -> -45566 | L49: =IF(K49<1,"VENCIDO","VIGENTE") -> VENCIDO
B50: Miguel193 | D50: +51 917 117 242 | E50: 1936 | G50: 8 | H50: 45564 | I50: 30 | J50: =+Table_714578[[#This Row],[FECHA DE INICIO]]+Table_714578[[#This Row],[DIAS]] -> 45594 | K50: =+Table_714578[[#This Row],[FECHA DE INICIO]]+Table_714578[[#This Row],[DIAS]]-TODAY() -> -2 | L50: =IF(K50<1,"VENCIDO","VIGENTE") -> VENCIDO
B51: Ingrid829 | D51: 51 986 430 133 | E51: 1946 | G51: 9 | H51: 45570 | I51: 30 | J51: =+Table_714578[[#This Row],[FECHA DE INICIO]]+Table_714578[[#This Row],[DIAS]] -> 45600 | K51: =+Table_714578[[#This Row],[FECHA DE INICIO]]+Table_714578[[#This Row],[DIAS]]-TODAY() -> 4 | L51: =IF(K51<1,"VENCIDO","VIGENTE") -> VIGENTE
B52: PERFILES : | E52: =SUM(E47:E51) -> 9793 | G52: =SUM(G47:G51) -> 25 | I52: 30 | J52: =+'star F (2)'!$H55+'star F (2)'!$I55 -> 0 | K52: ='star F (2)'!$H55+'star F (2)'!$I55-TODAY() -> -45596
A57: ALERTA DIAS
A58: =TODAY() -> 45596
A59: CUENTA | B59: NOMBRE | C59: CLAVE | D59: TELEFONO | E59: PIN PERFIL | F59: PRECIO US | G59: PRECIO | H59: FECHA DE INICIO | I59: DIAS | J59: FECHA DE VENCIMIENTO | K59: ALARMA | L59: ESTADO
...

Sheet Dis F
B5: ALERTA DIAS
B6: =TODAY() -> 45596
B7: CUENTA | C7: NOMBRE | D7: CLAVE | E7: TELEFONO | F7: PIN PERFIL | G7: PRECIO | H7: FECHA DE INICIO | I7: DIAS | J7: FECHA DE VENCIMIENTO | K7: ALARMA | L7: ESTADO
B8: Correo: cl294309@gmail.com Contraseña: dek548k | C8: joan | F8: 6548 | G8: 3.5 | H8: 45237 | I8: 30 | J8: =+'Dis F'!$H8+'Dis F'!$I8 -> 45267 | K8: ='Dis F'!$H8+'Dis F'!$I8-TODAY() -> -329 | L8: =IF(K8<1,"VENCIDO","VIGENTE") -> VENCIDO
C9: moises | F9: 6323 | G9: 3.5 | H9: 45233 | I9: 30 | J9: =+'Dis F'!$H9+'Dis F'!$I9 -> 45263 | K9: ='Dis F'!$H9+'Dis F'!$I9-TODAY() -> -333 | L9: =IF(K9<1,"VENCIDO","VIGENTE") -> VENCIDO
C10: akemi | F10: 2796 | G10: 3.5 | H10: 45238 | I10: 30 | J10: =+'Dis F'!$H10+'Dis F'!$I10 -> 45268 | K10: ='Dis F'!$H10+'Dis F'!$I10-TODAY() -> -328 | L10: =IF(K10<1,"VENCIDO","VIGENTE") -> VENCIDO
C11: ana | F11: 3696 | G11: 3.5 | H11: 45248 | I11: 30 | J11: =+'Dis F'!$H11+'Dis F'!$I11 -> 45278 | K11: ='Dis F'!$H11+'Dis F'!$I11-TODAY() -> -318 | L11: =IF(K11<1,"VENCIDO","VIGENTE") -> VENCIDO
C12: araceli | F12: 4333 | G12: 3.5 | H12: 45250 | I12: 30 | J12: =+'Dis F'!$H12+'Dis F'!$I12 -> 45280 | K12: ='Dis F'!$H12+'Dis F'!$I12-TODAY() -> -316 | L12: =IF(K12<1,"VENCIDO","VIGENTE") -> VENCIDO
C13: jimy | F13: 7812 | G13: 3.5 | H13: 45262 | I13: 30 | J13: =+'Dis F'!$H13+'Dis F'!$I13 -> 45292 | K13: ='Dis F'!$H13+'Dis F'!$I13-TODAY() -> -304 | L13: =IF(K13<1,"VENCIDO","VIGENTE") -> VENCIDO
C14: zuly7 | F14: 9349 | G14: 3.5 | H14: 45265 | I14: 30 | J14: =+'Dis F'!$H14+'Dis F'!$I14 -> 45295 | K14: ='Dis F'!$H14+'Dis F'!$I14-TODAY() -> -301 | L14: =IF(K14<1,"VENCIDO","VIGENTE") -> VENCIDO
C15: PERFILES : | F15: =SUM(F8:F14) -> 40857 | G15: =SUM(G8:G14) -> 24.5 | I15: 30 | J15: =+'Dis F'!$H15+'Dis F'!$I15 -> 30 | K15: ='Dis F'!$H15+'Dis F'!$I15-TODAY() -> -45566
B22: ALERTA DIAS
B23: =TODAY() -> 45596
B24: CUENTA | C24: NOMBRE | D24: CLAVE | E24: TELEFONO | F24: PIN PERFIL | G24: PRECIO | H24: FECHA DE INICIO | I24: DIAS | J24: FECHA DE VENCIMIENTO | K24: ALARMA | L24: ESTADO
B25: CORREO: guert2303dek@gmail.com CONTRASEÑA: de334me213 | C25: xioamara | F25: *876 | G25: 3.5 | H25: 45260 | I25: 30 | J25: =+'Dis F'!$H25+'Dis F'!$I25 -> 45290 | K25: ='Dis F'!$H25+'Dis F'!$I25-TODAY() -> -306 | L25: =IF(K25<1,"VENCIDO","VIGENTE") -> VENCIDO
C26: carlos | F26: 2559 | G26: 3.5 | H26: 45227 | I26: 60 | J26: =+'Dis F'!$H26+'Dis F'!$I26 -> 45287 | K26: ='Dis F'!$H26+'Dis F'!$I26-TODAY() -> -309 | L26: =IF(K26<1,"VENCIDO","VIGENTE") -> VENCIDO
C27: jean piere | F27: 1111 | G27: 3.5 | H27: 45253 | I27: 30 | J27: =+'Dis F'!$H27+'Dis F'!$I27 -> 45283 | K27: ='Dis F'!$H27+'Dis F'!$I27-TODAY() -> -313 | L27: =IF(K27<1,"VENCIDO","VIGENTE") -> VENCIDO
C28: keren | F28: 9468 | G28: 3.5 | H28: 45251 | I28: 30 | J28: =+'Dis F'!$H28+'Dis F'!$I28 -> 45281 | K28: ='Dis F'!$H28+'Dis F'!$I28-TODAY() -> -315 | L28: =IF(K28<1,"VENCIDO","VIGENTE") -> VENCIDO
C29: rosmery | F29: *785 | G29: 3.5 | H29: 45262 | I29: 30 | J29: =+'Dis F'!$H29+'Dis F'!$I29 -> 45292 | K29: ='Dis F'!$H29+'Dis F'!$I29-TODAY() -> -304 | L29: =IF(K29<1,"VENCIDO","VIGENTE") -> VENCIDO
C30: oriana | G30: 3.5 | H30: 45253 | I30: 30 | J30: =+'Dis F'!$H30+'Dis F'!$I30 -> 45283 | K30: ='Dis F'!$H30+'Dis F'!$I30-TODAY() -> -313 | L30: =IF(K30<1,"VENCIDO","VIGENTE") -> VENCIDO
F31: *876 | G31: 3.5 | I31: 30 | J31: =+'Dis F'!$H31+'Dis F'!$I31 -> 30 | K31: ='Dis F'!$H31+'Dis F'!$I31-TODAY() -> -45566 | L31: =IF(K31<1,"VENCIDO","VIGENTE") -> VENCIDO
C32: PERFILES : | F32: =SUM(F25:F31) -> 13138 | G32: =SUM(G25:G31) -> 24.5 | I32: 30 | J32: =+'Dis F'!$H32+'Dis F'!$I32 -> 30 | K32: ='Dis F'!$H32+'Dis F'!$I32-TODAY() -> -45566
B39: ALERTA DIAS
B40: =TODAY() -> 45596
B41: CUENTA | C41: NOMBRE | D41: CLAVE | E41: TELEFONO | F41: PIN PERFIL | G41: PRECIO | H41: FECHA DE INICIO | I41: DIAS | J41: FECHA DE VENCIMIENTO | K41: ALARMA | L41: ESTADO
B42: CORREO : lunigu332dek@gmail.com CONTRASEÑA: dek65mer573 | C42: diego9 | F42: 3456 | G42: 3.5 | H42: 45252 | I42: 30 | J42: =+'Dis F'!$H42+'Dis F'!$I42 -> 45282 | K42: ='Dis F'!$H42+'Dis F'!$I42-TODAY() -> -314 | L42: =IF(K42<1,"VENCIDO","VIGENTE") -> VENCIDO
C43: briseida | F43: 6975 | G43: 3.5 | H43: 45237 | I43: 30 | J43: =+'Dis F'!$H43+'Dis F'!$I43 -> 45267 | K43: ='Dis F'!$H43+'Dis F'!$I43-TODAY() -> -329 | L43: =IF(K43<1,"VENCIDO","VIGENTE") -> VENCIDO
C44: aleksandro | F44: 864 | G44: 3.5 | H44: 45248 | I44: 30 | J44: =+'Dis F'!$H44+'Dis F'!$I44 -> 45278 | K44: ='Dis F'!$H44+'Dis F'!$I44-TODAY() -> -318 | L44: =IF(K44<1,"VENCIDO","VIGENTE") -> VENCIDO
C45: jesus | F45: 4545 | G45: 3.5 | H45: 45241 | I45: 30 | J45: =+'Dis F'!$H45+'Dis F'!$I45 -> 45271 | K45: ='Dis F'!$H45+'Dis F'!$I45-TODAY() -> -325 | L45: =IF(K45<1,"VENCIDO","VIGENTE") -> VENCIDO
C46: miguel | F46: 4545 | G46: 3.5 | H46: 45234 | I46: 30 | J46: =+'Dis F'!$H46+'Dis F'!$I46 -> 45264 | K46: ='Dis F'!$H46+'Dis F'!$I46-TODAY() -> -332 | L46: =IF(K46<1,"VENCIDO","VIGENTE") -> VENCIDO
C47: aleksandro | F47: ***3 | G47: 3.5 | H47: 45248 | I47: 30 | J47: =+'Dis F'!$H47+'Dis F'!$I47 -> 45278 | K47: ='Dis F'!$H47+'Dis F'!$I47-TODAY() -> -318 | L47: =IF(K47<1,"VENCIDO","VIGENTE") -> VENCIDO
C48: dany e | G48: 3.5 | H48: 45260 | I48: 30 | J48: =+'Dis F'!$H48+'Dis F'!$I48 -> 45290 | K48: ='Dis F'!$H48+'Dis F'!$I48-TODAY() -> -306 | L48: =IF(K48<1,"VENCIDO","VIGENTE") -> VENCIDO
C49: PERFILES : | F49: =SUM(F42:F48) -> 20385 | G49: =SUM(G42:G48) -> 24.5 | I49: 30 | J49: =+'Dis F'!$H49+'Dis F'!$I49 -> 30 | K49: ='Dis F'!$H49+'Dis F'!$I49-TODAY() -> -45566
B57: ALERTA DIAS
B58: =TODAY() -> 45596
B59: CUENTA | C59: NOMBRE | D59: CLAVE | E59: TELEFONO | F59: PIN PERFIL | G59: PRECIO | H59: FECHA DE INICIO | I59: DIAS | J59: FECHA DE VENCIMIENTO | K59: ALARMA | L59: ESTADO
B60: Correo : deku75490stream@gmail.com Contraseña : dek852mure | C60: gabo16 | F60: 2838 | G60: =IF(H60>0,7,0) -> 7 | H60: 45260 | I60: 30 | J60: =+'Dis F'!$H60+'Dis F'!$I60 -> 45290 | K60: ='Dis F'!$H60+'Dis F'!$I60-TODAY() -> -306 | L60: =IF(K60<1,"VENCIDO","VIGENTE") -> VENCIDO
C61: gabo18 | F61: 2937 | G61: =IF(H61>0,7,0) -> 7 | H61: 45260 | I61: 30 | J61: =+'Dis F'!$H61+'Dis F'!$I61 -> 45290 | K61: ='Dis F'!$H61+'Dis F'!$I61-TODAY() -> -306 | L61: =IF(K61<1,"VENCIDO","VIGENTE") -> VENCIDO
G62: =IF(H62>0,7,0) -> 0 | I62: 30 | J62: =+'Dis F'!$H62+'Dis F'!$I62 -> 30 | K62: ='Dis F'!$H62+'Dis F'!$I62-TODAY() -> -45566 | L62: =IF(K62<1,"VENCIDO","VIGENTE") -> VENCIDO
G63: =IF(H63>0,7,0) -> 0 | I63: 30 | J63: =+'Dis F'!$H63+'Dis F'!$I63 -> 30 | K63: ='Dis F'!$H63+'Dis F'!$I63-TODAY() -> -45566 | L63: =IF(K63<1,"VENCIDO","VIGENTE") -> VENCIDO
...

Sheet Dis R
B5: Jhosut
B6: =TODAY() -> 45596
B7: CUENTA | C7: Contraseña | D7: CLAVE | E7: Facturacion | F7: PIN PERFIL | G7: PRECIO | H7: FECHA DE INICIO | I7: DIAS | J7: FECHA DE VENCIMIENTO | K7: ALARMA | L7: ESTADO
C8: dek356bert3 | D8: Junior2847 | F8: 6885 | G8: =IF(H8>0,5,0) -> 5 | H8: 45560 | I8: 30 | J8: =+'Dis R'!$H8+'Dis R'!$I8 -> 45590 | K8: ='Dis R'!$H8+'Dis R'!$I8-TODAY() -> -6 | L8: =IF(K8<1,"VENCIDO","VIGENTE") -> VENCIDO
G9: =IF(H9>0,10,0) -> 0 | I9: 30 | J9: =+'Dis R'!$H9+'Dis R'!$I9 -> 30 | K9: ='Dis R'!$H9+'Dis R'!$I9-TODAY() -> -45566 | L9: =IF(K9<1,"VENCIDO","VIGENTE") -> VENCIDO
G10: =IF(H10>0,10,0) -> 0 | I10: 30 | J10: =+'Dis R'!$H10+'Dis R'!$I10 -> 30 | K10: ='Dis R'!$H10+'Dis R'!$I10-TODAY() -> -45566 | L10: =IF(K10<1,"VENCIDO","VIGENTE") -> VENCIDO
G11: =IF(H11>0,10,0) -> 0 | I11: 30 | J11: =+'Dis R'!$H11+'Dis R'!$I11 -> 30 | K11: ='Dis R'!$H11+'Dis R'!$I11-TODAY() -> -45566 | L11: =IF(K11<1,"VENCIDO","VIGENTE") -> VENCIDO
G12: =IF(H12>0,10,0) -> 0 | I12: 30 | J12: =+'Dis R'!$H12+'Dis R'!$I12 -> 30 | K12: ='Dis R'!$H12+'Dis R'!$I12-TODAY() -> -45566 | L12: =IF(K12<1,"VENCIDO","VIGENTE") -> VENCIDO
G13: =IF(H13>0,10,0) -> 0 | I13: 30 | J13: =+'Dis R'!$H13+'Dis R'!$I13 -> 30 | K13: ='Dis R'!$H13+'Dis R'!$I13-TODAY() -> -45566 | L13: =IF(K13<1,"VENCIDO","VIGENTE") -> VENCIDO
G14: =IF(H14>0,10,0) -> 0 | I14: 30 | J14: =+'Dis R'!$H14+'Dis R'!$I14 -> 30 | K14: ='Dis R'!$H14+'Dis R'!$I14-TODAY() -> -45566 | L14: =IF(K14<1,"VENCIDO","VIGENTE") -> VENCIDO
G15: =IF(H15>0,10,0) -> 0 | I15: 30 | J15: =+'Dis R'!$H15+'Dis R'!$I15 -> 30 | K15: ='Dis R'!$H15+'Dis R'!$I15-TODAY() -> -45566 | L15: =IF(K15<1,"VENCIDO","VIGENTE") -> VENCIDO
G16: =IF(H16>0,10,0) -> 0 | I16: 30 | J16: =+'Dis R'!$H16+'Dis R'!$I16 -> 30 | K16: ='Dis R'!$H16+'Dis R'!$I16-TODAY() -> -45566 | L16: =IF(K16<1,"VENCIDO","VIGENTE") -> VENCIDO
G17: =IF(H17>0,10,0) -> 0 | I17: 30 | J17: =+'Dis R'!$H17+'Dis R'!$I17 -> 30 | K17: ='Dis R'!$H17+'Dis R'!$I17-TODAY() -> -45566 | L17: =IF(K17<1,"VENCIDO","VIGENTE") -> VENCIDO
G18: =IF(H18>0,10,0) -> 0 | I18: 30 | J18: =+'Dis R'!$H18+'Dis R'!$I18 -> 30 | K18: ='Dis R'!$H18+'Dis R'!$I18-TODAY() -> -45566 | L18: =IF(K18<1,"VENCIDO","VIGENTE") -> VENCIDO
G19: =IF(H19>0,10,0) -> 0 | I19: 30 | J19: =+'Dis R'!$H19+'Dis R'!$I19 -> 30 | K19: ='Dis R'!$H19+'Dis R'!$I19-TODAY() -> -45566 | L19: =IF(K19<1,"VENCIDO","VIGENTE") -> VENCIDO
G20: =IF(H20>0,10,0) -> 0 | I20: 30 | J20: =+'Dis R'!$H20+'Dis R'!$I20 -> 30 | K20: ='Dis R'!$H20+'Dis R'!$I20-TODAY() -> -45566 | L20: =IF(K20<1,"VENCIDO","VIGENTE") -> VENCIDO
G21: =SUM(G8:G20) -> 5
B26: Yaear
B27: =TODAY() -> 45596 | C27: cl294309@gmail.com | G27: saya dolares
B28: CUENTA | C28: Contraseña | D28: CLAVE | E28: Facturacion | F28: PIN PERFIL | G28: PRECIO | H28: FECHA DE INICIO | I28: DIAS | J28: FECHA DE VENCIMIENTO | K28: ALARMA | L28: ESTADO
B29: saya37 | C29: dek35ner46 | F29: 6004 | G29: =IF(H29>0,1.5,0) -> 1.5 | H29: 45428 | I29: 30 | J29: =+'Dis R'!$H29+'Dis R'!$I29 -> 45458 | K29: ='Dis R'!$H29+'Dis R'!$I29-TODAY() -> -138 | L29: =IF(K29<1,"VENCIDO","VIGENTE") -> VENCIDO
B30: Pamela64 | C30: dek35ner47 | F30: 8445 | G30: =IF(H30>0,5,0) -> 5 | H30: 45428 | I30: 30 | J30: =+'Dis R'!$H30+'Dis R'!$I30 -> 45458 | K30: ='Dis R'!$H30+'Dis R'!$I30-TODAY() -> -138 | L30: =IF(K30<1,"VENCIDO","VIGENTE") -> VENCIDO
G31: =IF(H31>0,10,0) -> 0 | I31: 30 | J31: =+'Dis R'!$H31+'Dis R'!$I31 -> 30 | K31: ='Dis R'!$H31+'Dis R'!$I31-TODAY() -> -45566 | L31: =IF(K31<1,"VENCIDO","VIGENTE") -> VENCIDO
G32: =IF(H32>0,10,0) -> 0 | I32: 30 | J32: =+'Dis R'!$H32+'Dis R'!$I32 -> 30 | K32: ='Dis R'!$H32+'Dis R'!$I32-TODAY() -> -45566 | L32: =IF(K32<1,"VENCIDO","VIGENTE") -> VENCIDO
G33: =IF(H33>0,10,0) -> 0 | I33: 30 | J33: =+'Dis R'!$H33+'Dis R'!$I33 -> 30 | K33: ='Dis R'!$H33+'Dis R'!$I33-TODAY() -> -45566 | L33: =IF(K33<1,"VENCIDO","VIGENTE") -> VENCIDO
G34: =IF(H34>0,10,0) -> 0 | I34: 30 | J34: =+'Dis R'!$H34+'Dis R'!$I34 -> 30 | K34: ='Dis R'!$H34+'Dis R'!$I34-TODAY() -> -45566 | L34: =IF(K34<1,"VENCIDO","VIGENTE") -> VENCIDO
G35: =IF(H35>0,10,0) -> 0 | I35: 30 | J35: =+'Dis R'!$H35+'Dis R'!$I35 -> 30 | K35: ='Dis R'!$H35+'Dis R'!$I35-TODAY() -> -45566 | L35: =IF(K35<1,"VENCIDO","VIGENTE") -> VENCIDO
G36: =IF(H36>0,10,0) -> 0 | I36: 30 | J36: =+'Dis R'!$H36+'Dis R'!$I36 -> 30 | K36: ='Dis R'!$H36+'Dis R'!$I36-TODAY() -> -45566 | L36: =IF(K36<1,"VENCIDO","VIGENTE") -> VENCIDO
G37: =IF(H37>0,10,0) -> 0 | I37: 30 | J37: =+'Dis R'!$H37+'Dis R'!$I37 -> 30 | K37: ='Dis R'!$H37+'Dis R'!$I37-TODAY() -> -45566 | L37: =IF(K37<1,"VENCIDO","VIGENTE") -> VENCIDO
G38: =IF(H38>0,10,0) -> 0 | I38: 30 | J38: =+'Dis R'!$H38+'Dis R'!$I38 -> 30 | K38: ='Dis R'!$H38+'Dis R'!$I38-TODAY() -> -45566 | L38: =IF(K38<1,"VENCIDO","VIGENTE") -> VENCIDO
G39: =IF(H39>0,10,0) -> 0 | I39: 30 | J39: =+'Dis R'!$H39+'Dis R'!$I39 -> 30 | K39: ='Dis R'!$H39+'Dis R'!$I39-TODAY() -> -45566 | L39: =IF(K39<1,"VENCIDO","VIGENTE") -> VENCIDO
G40: =IF(H40>0,10,0) -> 0 | I40: 30 | J40: =+'Dis R'!$H40+'Dis R'!$I40 -> 30 | K40: ='Dis R'!$H40+'Dis R'!$I40-TODAY() -> -45566 | L40: =IF(K40<1,"VENCIDO","VIGENTE") -> VENCIDO
G41: =IF(H41>0,10,0) -> 0 | I41: 30 | J41: =+'Dis R'!$H41+'Dis R'!$I41 -> 30 | K41: ='Dis R'!$H41+'Dis R'!$I41-TODAY() -> -45566 | L41: =IF(K41<1,"VENCIDO","VIGENTE") -> VENCIDO
G42: =SUM(G29:G41) -> 6.5
B47: Franco Jeyli
B48: =TODAY() -> 45596
B49: CUENTA | C49: Contraseña | D49: CLAVE | E49: Facturacion | F49: PIN PERFIL | G49: PRECIO | H49: FECHA DE INICIO | I49: DIAS | J49: FECHA DE VENCIMIENTO | K49: ALARMA | L49: ESTADO
G50: =IF(H50>0,10,0) -> 0 | I50: 30 | J50: =+'Dis R'!$H50+'Dis R'!$I50 -> 30 | K50: ='Dis R'!$H50+'Dis R'!$I50-TODAY() -> -45566 | L50: =IF(K50<1,"VENCIDO","VIGENTE") -> VENCIDO
G51: =IF(H51>0,10,0) -> 0 | I51: 30 | J51: =+'Dis R'!$H51+'Dis R'!$I51 -> 30 | K51: ='Dis R'!$H51+'Dis R'!$I51-TODAY() -> -45566 | L51: =IF(K51<1,"VENCIDO","VIGENTE") -> VENCIDO
G52: =IF(H52>0,10,0) -> 0 | I52: 30 | J52: =+'Dis R'!$H52+'Dis R'!$I52 -> 30 | K52: ='Dis R'!$H52+'Dis R'!$I52-TODAY() -> -45566 | L52: =IF(K52<1,"VENCIDO","VIGENTE") -> VENCIDO
...

Sheet Com R
B5: Hector
B6: =TODAY() -> 45596
B7: CUENTA | C7: Contraseña | D7: CLAVE | E7: Facturacion | F7: PIN PERFIL | G7: PRECIO | H7: FECHA DE INICIO | I7: DIAS | J7: FECHA DE VENCIMIENTO | K7: ALARMA | L7: ESTADO
C8: vwh9yEe5tX | G8: =IF(H8>0,17,0) -> 0 | I8: 30 | J8: =+'Com R'!$H8+'Com R'!$I8 -> 30 | K8: ='Com R'!$H8+'Com R'!$I8-TODAY() -> -45566 | L8: =IF(K8<1,"VENCIDO","VIGENTE") -> VENCIDO
G9: =IF(H9>0,17,0) -> 0 | I9: 30 | J9: =+'Com R'!$H9+'Com R'!$I9 -> 30 | K9: ='Com R'!$H9+'Com R'!$I9-TODAY() -> -45566 | L9: =IF(K9<1,"VENCIDO","VIGENTE") -> VENCIDO
G10: =IF(H10>0,17,0) -> 0 | I10: 30 | J10: =+'Com R'!$H10+'Com R'!$I10 -> 30 | K10: ='Com R'!$H10+'Com R'!$I10-TODAY() -> -45566 | L10: =IF(K10<1,"VENCIDO","VIGENTE") -> VENCIDO
G11: =IF(H11>0,17,0) -> 0 | I11: 30 | J11: =+'Com R'!$H11+'Com R'!$I11 -> 30 | K11: ='Com R'!$H11+'Com R'!$I11-TODAY() -> -45566 | L11: =IF(K11<1,"VENCIDO","VIGENTE") -> VENCIDO
G12: =IF(H12>0,17,0) -> 0 | I12: 30 | J12: =+'Com R'!$H12+'Com R'!$I12 -> 30 | K12: ='Com R'!$H12+'Com R'!$I12-TODAY() -> -45566 | L12: =IF(K12<1,"VENCIDO","VIGENTE") -> VENCIDO
G13: =IF(H13>0,17,0) -> 0 | I13: 30 | J13: =+'Com R'!$H13+'Com R'!$I13 -> 30 | K13: ='Com R'!$H13+'Com R'!$I13-TODAY() -> -45566 | L13: =IF(K13<1,"VENCIDO","VIGENTE") -> VENCIDO
G14: =IF(H14>0,17,0) -> 0 | I14: 30 | J14: =+'Com R'!$H14+'Com R'!$I14 -> 30 | K14: ='Com R'!$H14+'Com R'!$I14-TODAY() -> -45566 | L14: =IF(K14<1,"VENCIDO","VIGENTE") -> VENCIDO
G15: =IF(H15>0,17,0) -> 0 | I15: 30 | J15: =+'Com R'!$H15+'Com R'!$I15 -> 30 | K15: ='Com R'!$H15+'Com R'!$I15-TODAY() -> -45566 | L15: =IF(K15<1,"VENCIDO","VIGENTE") -> VENCIDO
G16: =IF(H16>0,17,0) -> 0 | I16: 30 | J16: =+'Com R'!$H16+'Com R'!$I16 -> 30 | K16: ='Com R'!$H16+'Com R'!$I16-TODAY() -> -45566 | L16: =IF(K16<1,"VENCIDO","VIGENTE") -> VENCIDO
G17: =IF(H17>0,17,0) -> 0 | I17: 30 | J17: =+'Com R'!$H17+'Com R'!$I17 -> 30 | K17: ='Com R'!$H17+'Com R'!$I17-TODAY() -> -45566 | L17: =IF(K17<1,"VENCIDO","VIGENTE") -> VENCIDO
G18: =IF(H18>0,17,0) -> 0 | I18: 30 | J18: =+'Com R'!$H18+'Com R'!$I18 -> 30 | K18: ='Com R'!$H18+'Com R'!$I18-TODAY() -> -45566 | L18: =IF(K18<1,"VENCIDO","VIGENTE") -> VENCIDO
G19: =IF(H19>0,17,0) -> 0 | I19: 30 | J19: =+'Com R'!$H19+'Com R'!$I19 -> 30 | K19: ='Com R'!$H19+'Com R'!$I19-TODAY() -> -45566 | L19: =IF(K19<1,"VENCIDO","VIGENTE") -> VENCIDO
G20: =IF(H20>0,17,0) -> 0 | I20: 30 | J20: =+'Com R'!$H20+'Com R'!$I20 -> 30 | K20: ='Com R'!$H20+'Com R'!$I20-TODAY() -> -45566 | L20: =IF(K20<1,"VENCIDO","VIGENTE") -> VENCIDO
G21: =SUM(G8:G20) -> 0
B26: Jhosut
B27: =TODAY() -> 45596
B28: CUENTA | C28: Contraseña | D28: CLAVE | E28: Facturacion | F28: PIN PERFIL | G28: PRECIO | H28: FECHA DE INICIO | I28: DIAS | J28: FECHA DE VENCIMIENTO | K28: ALARMA | L28: ESTADO
G29: =IF(H29>0,17,0) -> 0 | I29: 30 | J29: =+'Com R'!$H29+'Com R'!$I29 -> 30 | K29: ='Com R'!$H29+'Com R'!$I29-TODAY() -> -45566 | L29: =IF(K29<1,"VENCIDO","VIGENTE") -> VENCIDO
G30: =IF(H30>0,17,0) -> 0 | I30: 30 | J30: =+'Com R'!$H30+'Com R'!$I30 -> 30 | K30: ='Com R'!$H30+'Com R'!$I30-TODAY() -> -45566 | L30: =IF(K30<1,"VENCIDO","VIGENTE") -> VENCIDO
G31: =IF(H31>0,17,0) -> 0 | I31: 30 | J31: =+'Com R'!$H31+'Com R'!$I31 -> 30 | K31: ='Com R'!$H31+'Com R'!$I31-TODAY() -> -45566 | L31: =IF(K31<1,"VENCIDO","VIGENTE") -> VENCIDO
G32: =IF(H32>0,17,0) -> 0 | I32: 30 | J32: =+'Com R'!$H32+'Com R'!$I32 -> 30 | K32: ='Com R'!$H32+'Com R'!$I32-TODAY() -> -45566 | L32: =IF(K32<1,"VENCIDO","VIGENTE") -> VENCIDO
G33: =IF(H33>0,17,0) -> 0 | I33: 30 | J33: =+'Com R'!$H33+'Com R'!$I33 -> 30 | K33: ='Com R'!$H33+'Com R'!$I33-TODAY() -> -45566 | L33: =IF(K33<1,"VENCIDO","VIGENTE") -> VENCIDO
G34: =IF(H34>0,17,0) -> 0 | I34: 30 | J34: =+'Com R'!$H34+'Com R'!$I34 -> 30 | K34: ='Com R'!$H34+'Com R'!$I34-TODAY() -> -45566 | L34: =IF(K34<1,"VENCIDO","VIGENTE") -> VENCIDO
G35: =IF(H35>0,17,0) -> 0 | I35: 30 | J35: =+'Com R'!$H35+'Com R'!$I35 -> 30 | K35: ='Com R'!$H35+'Com R'!$I35-TODAY() -> -45566 | L35: =IF(K35<1,"VENCIDO","VIGENTE") -> VENCIDO
G36: =IF(H36>0,17,0) -> 0 | I36: 30 | J36: =+'Com R'!$H36+'Com R'!$I36 -> 30 | K36: ='Com R'!$H36+'Com R'!$I36-TODAY() -> -45566 | L36: =IF(K36<1,"VENCIDO","VIGENTE") -> VENCIDO
G37: =IF(H37>0,17,0) -> 0 | I37: 30 | J37: =+'Com R'!$H37+'Com R'!$I37 -> 30 | K37: ='Com R'!$H37+'Com R'!$I37-TODAY() -> -45566 | L37: =IF(K37<1,"VENCIDO","VIGENTE") -> VENCIDO
G38: =IF(H38>0,17,0) -> 0 | I38: 30 | J38: =+'Com R'!$H38+'Com R'!$I38 -> 30 | K38: ='Com R'!$H38+'Com R'!$I38-TODAY() -> -45566 | L38: =IF(K38<1,"VENCIDO","VIGENTE") -> VENCIDO
G39: =IF(H39>0,17,0) -> 0 | I39: 30 | J39: =+'Com R'!$H39+'Com R'!$I39 -> 30 | K39: ='Com R'!$H39+'Com R'!$I39-TODAY() -> -45566 | L39: =IF(K39<1,"VENCIDO","VIGENTE") -> VENCIDO
G40: =IF(H40>0,17,0) -> 0 | I40: 30 | J40: =+'Com R'!$H40+'Com R'!$I40 -> 30 | K40: ='Com R'!$H40+'Com R'!$I40-TODAY() -> -45566 | L40: =IF(K40<1,"VENCIDO","VIGENTE") -> VENCIDO
G41: =IF(H41>0,17,0) -> 0 | I41: 30 | J41: =+'Com R'!$H41+'Com R'!$I41 -> 30 | K41: ='Com R'!$H41+'Com R'!$I41-TODAY() -> -45566 | L41: =IF(K41<1,"VENCIDO","VIGENTE") -> VENCIDO
G42: =SUM(G29:G41) -> 0
B48: =TODAY() -> 45596
B49: CUENTA | C49: Contraseña | D49: CLAVE | E49: Facturacion | F49: PIN PERFIL | G49: PRECIO | H49: FECHA DE INICIO | I49: DIAS | J49: FECHA DE VENCIMIENTO | K49: ALARMA | L49: ESTADO
G50: =IF(H50>0,17,0) -> 0 | I50: 30 | J50: =+'Com R'!$H50+'Com R'!$I50 -> 30 | K50: ='Com R'!$H50+'Com R'!$I50-TODAY() -> -45566 | L50: =IF(K50<1,"VENCIDO","VIGENTE") -> VENCIDO
G51: =IF(H51>0,17,0) -> 0 | I51: 30 | J51: =+'Com R'!$H51+'Com R'!$I51 -> 30 | K51: ='Com R'!$H51+'Com R'!$I51-TODAY() -> -45566 | L51: =IF(K51<1,"VENCIDO","VIGENTE") -> VENCIDO
G52: =IF(H52>0,17,0) -> 0 | I52: 30 | J52: =+'Com R'!$H52+'Com R'!$I52 -> 30 | K52: ='Com R'!$H52+'Com R'!$I52-TODAY() -> -45566 | L52: =IF(K52<1,"VENCIDO","VIGENTE") -> VENCIDO
G53: =IF(H53>0,17,0) -> 0 | I53: 30 | J53: =+'Com R'!$H53+'Com R'!$I53 -> 30 | K53: ='Com R'!$H53+'Com R'!$I53-TODAY() -> -45566 | L53: =IF(K53<1,"VENCIDO","VIGENTE") -> VENCIDO
...

Sheet Com F
B5: ALERTA DIAS
B6: =TODAY() -> 45596
B7: CUENTA | C7: NOMBRE | D7: CLAVE | E7: TELEFONO | F7: PIN PERFIL | G7: PRECIO | H7: FECHA DE INICIO | I7: DIAS | J7: FECHA DE VENCIMIENTO | K7: ALARMA | L7: ESTADO
G8: =IF(H8>0,7,0) -> 0 | I8: 30 | J8: =+'Com F'!$H8+'Com F'!$I8 -> 30 | K8: ='Com F'!$H8+'Com F'!$I8-TODAY() -> -45566 | L8: =IF(K8<1,"VENCIDO","VIGENTE") -> VENCIDO
G9: =IF(H9>0,7,0) -> 0 | I9: 30 | J9: =+'Com F'!$H9+'Com F'!$I9 -> 30 | K9: ='Com F'!$H9+'Com F'!$I9-TODAY() -> -45566 | L9: =IF(K9<1,"VENCIDO","VIGENTE") -> VENCIDO
G10: =IF(H10>0,7,0) -> 0 | I10: 30 | J10: =+'Com F'!$H10+'Com F'!$I10 -> 30 | K10: ='Com F'!$H10+'Com F'!$I10-TODAY() -> -45566 | L10: =IF(K10<1,"VENCIDO","VIGENTE") -> VENCIDO
G11: =IF(H11>0,7,0) -> 0 | I11: 30 | J11: =+'Com F'!$H11+'Com F'!$I11 -> 30 | K11: ='Com F'!$H11+'Com F'!$I11-TODAY() -> -45566 | L11: =IF(K11<1,"VENCIDO","VIGENTE") -> VENCIDO
G12: =IF(H12>0,7,0) -> 0 | I12: 30 | J12: =+'Com F'!$H12+'Com F'!$I12 -> 30 | K12: ='Com F'!$H12+'Com F'!$I12-TODAY() -> -45566 | L12: =IF(K12<1,"VENCIDO","VIGENTE") -> VENCIDO
G13: =IF(H13>0,7,0) -> 0 | I13: 30 | J13: =+'Com F'!$H13+'Com F'!$I13 -> 30 | K13: ='Com F'!$H13+'Com F'!$I13-TODAY() -> -45566 | L13: =IF(K13<1,"VENCIDO","VIGENTE") -> VENCIDO
G14: =IF(H14>0,7,0) -> 0 | I14: 90 | J14: =+'Com F'!$H14+'Com F'!$I14 -> 90 | K14: ='Com F'!$H14+'Com F'!$I14-TODAY() -> -45506 | L14: =IF(K14<1,"VENCIDO","VIGENTE") -> VENCIDO
C15: PERFILES : | F15: =SUM(F8:F14) -> 0 | G15: =SUM(G8:G14) -> 0
B20: =TODAY() -> 45596
B21: CUENTA | C21: NOMBRE | D21: CLAVE | E21: TELEFONO | F21: PIN PERFIL | G21: PRECIO | H21: FECHA DE INICIO | I21: DIAS | J21: FECHA DE VENCIMIENTO | K21: ALARMA | L21: ESTADO
C22: Moisrs76 | D22: dek57ner77 | E22: 51 986 430 133 | F22: 2633 | G22: =IF(H22>0,9,0) -> 9 | H22: 45570 | I22: 30 | J22: =+'Com F'!$H22+'Com F'!$I22 -> 45600 | K22: ='Com F'!$H22+'Com F'!$I22-TODAY() -> 4 | L22: =IF(K22<1,"VENCIDO","VIGENTE") -> VIGENTE
G23: =IF(H23>0,7,0) -> 0 | I23: 30 | J23: =+'Com F'!$H23+'Com F'!$I23 -> 30 | K23: ='Com F'!$H23+'Com F'!$I23-TODAY() -> -45566 | L23: =IF(K23<1,"VENCIDO","VIGENTE") -> VENCIDO
G24: =IF(H24>0,7,0) -> 0 | I24: 30 | J24: =+'Com F'!$H24+'Com F'!$I24 -> 30 | K24: ='Com F'!$H24+'Com F'!$I24-TODAY() -> -45566 | L24: =IF(K24<1,"VENCIDO","VIGENTE") -> VENCIDO
G25: =IF(H25>0,7,0) -> 0 | I25: 30 | J25: =+'Com F'!$H25+'Com F'!$I25 -> 30 | K25: ='Com F'!$H25+'Com F'!$I25-TODAY() -> -45566 | L25: =IF(K25<1,"VENCIDO","VIGENTE") -> VENCIDO
G26: =IF(H26>0,7,0) -> 0 | I26: 30 | J26: =+'Com F'!$H26+'Com F'!$I26 -> 30 | K26: ='Com F'!$H26+'Com F'!$I26-TODAY() -> -45566 | L26: =IF(K26<1,"VENCIDO","VIGENTE") -> VENCIDO
G27: =IF(H27>0,7,0) -> 0 | I27: 30 | J27: =+'Com F'!$H27+'Com F'!$I27 -> 30 | K27: ='Com F'!$H27+'Com F'!$I27-TODAY() -> -45566 | L27: =IF(K27<1,"VENCIDO","VIGENTE") -> VENCIDO
G28: =IF(H28>0,7,0) -> 0 | I28: 90 | J28: =+'Com F'!$H28+'Com F'!$I28 -> 90 | K28: ='Com F'!$H28+'Com F'!$I28-TODAY() -> -45506 | L28: =IF(K28<1,"VENCIDO","VIGENTE") -> VENCIDO
C29: PERFILES : | F29: =SUM(F22:F28) -> 2633 | G29: =SUM(G22:G28) -> 9
B34: =TODAY() -> 45596
B35: CUENTA | C35: NOMBRE | D35: CLAVE | E35: TELEFONO | F35: PIN PERFIL | G35: PRECIO | H35: FECHA DE INICIO | I35: DIAS | J35: FECHA DE VENCIMIENTO | K35: ALARMA | L35: ESTADO
G36: =IF(H36>0,7,0) -> 0 | I36: 30 | J36: =+'Com F'!$H36+'Com F'!$I36 -> 30 | K36: ='Com F'!$H36+'Com F'!$I36-TODAY() -> -45566 | L36: =IF(K36<1,"VENCIDO","VIGENTE") -> VENCIDO
G37: =IF(H37>0,7,0) -> 0 | I37: 30 | J37: =+'Com F'!$H37+'Com F'!$I37 -> 30 | K37: ='Com F'!$H37+'Com F'!$I37-TODAY() -> -45566 | L37: =IF(K37<1,"VENCIDO","VIGENTE") -> VENCIDO
G38: =IF(H38>0,7,0) -> 0 | I38: 30 | J38: =+'Com F'!$H38+'Com F'!$I38 -> 30 | K38: ='Com F'!$H38+'Com F'!$I38-TODAY() -> -45566 | L38: =IF(K38<1,"VENCIDO","VIGENTE") -> VENCIDO
G39: =IF(H39>0,7,0) -> 0 | I39: 30 | J39: =+'Com F'!$H39+'Com F'!$I39 -> 30 | K39: ='Com F'!$H39+'Com F'!$I39-TODAY() -> -45566 | L39: =IF(K39<1,"VENCIDO","VIGENTE") -> VENCIDO
G40: =IF(H40>0,7,0) -> 0 | I40: 30 | J40: =+'Com F'!$H40+'Com F'!$I40 -> 30 | K40: ='Com F'!$H40+'Com F'!$I40-TODAY() -> -45566 | L40: =IF(K40<1,"VENCIDO","VIGENTE") -> VENCIDO
G41: =IF(H41>0,7,0) -> 0 | I41: 30 | J41: =+'Com F'!$H41+'Com F'!$I41 -> 30 | K41: ='Com F'!$H41+'Com F'!$I41-TODAY() -> -45566 | L41: =IF(K41<1,"VENCIDO","VIGENTE") -> VENCIDO
G42: =IF(H42>0,7,0) -> 0 | I42: 90 | J42: =+'Com F'!$H42+'Com F'!$I42 -> 90 | K42: ='Com F'!$H42+'Com F'!$I42-TODAY() -> -45506 | L42: =IF(K42<1,"VENCIDO","VIGENTE") -> VENCIDO
C43: PERFILES : | F43: =SUM(F36:F42) -> 0 | G43: =SUM(G36:G42) -> 0
B48: =TODAY() -> 45596
B49: CUENTA | C49: NOMBRE | D49: CLAVE | E49: TELEFONO | F49: PIN PERFIL | G49: PRECIO | H49: FECHA DE INICIO | I49: DIAS | J49: FECHA DE VENCIMIENTO | K49: ALARMA | L49: ESTADO
G50: =IF(H50>0,7,0) -> 0 | I50: 30 | J50: =+'Com F'!$H50+'Com F'!$I50 -> 30 | K50: ='Com F'!$H50+'Com F'!$I50-TODAY() -> -45566 | L50: =IF(K50<1,"VENCIDO","VIGENTE") -> VENCIDO
G51: =IF(H51>0,7,0) -> 0 | I51: 30 | J51: =+'Com F'!$H51+'Com F'!$I51 -> 30 | K51: ='Com F'!$H51+'Com F'!$I51-TODAY() -> -45566 | L51: =IF(K51<1,"VENCIDO","VIGENTE") -> VENCIDO
G52: =IF(H52>0,7,0) -> 0 | I52: 30 | J52: =+'Com F'!$H52+'Com F'!$I52 -> 30 | K52: ='Com F'!$H52+'Com F'!$I52-TODAY() -> -45566 | L52: =IF(K52<1,"VENCIDO","VIGENTE") -> VENCIDO
G53: =IF(H53>0,7,0) -> 0 | I53: 30 | J53: =+'Com F'!$H53+'Com F'!$I53 -> 30 | K53: ='Com F'!$H53+'Com F'!$I53-TODAY() -> -45566 | L53: =IF(K53<1,"VENCIDO","VIGENTE") -> VENCIDO
G54: =IF(H54>0,7,0) -> 0 | I54: 30 | J54: =+'Com F'!$H54+'Com F'!$I54 -> 30 | K54: ='Com F'!$H54+'Com F'!$I54-TODAY() -> -45566 | L54: =IF(K54<1,"VENCIDO","VIGENTE") -> VENCIDO
G55: =IF(H55>0,7,0) -> 0 | I55: 30 | J55: =+'Com F'!$H55+'Com F'!$I55 -> 30 | K55: ='Com F'!$H55+'Com F'!$I55-TODAY() -> -45566 | L55: =IF(K55<1,"VENCIDO","VIGENTE") -> VENCIDO
G56: =IF(H56>0,7,0) -> 0 | I56: 90 | J56: =+'Com F'!$H56+'Com F'!$I56 -> 90 | K56: ='Com F'!$H56+'Com F'!$I56-TODAY() -> -45506 | L56: =IF(K56<1,"VENCIDO","VIGENTE") -> VENCIDO
...

Sheet HBO F
B5: ALERTA DIAS
B6: =TODAY() -> 45596
B7: CUENTA | C7: NOMBRE | D7: CLAVE | E7: TELEFONO | F7: PIN PERFIL | G7: PRECIO | H7: FECHA DE INICIO | I7: DIAS | J7: FECHA DE VENCIMIENTO | K7: ALARMA | L7: ESTADO
B8: Correo: ctisfer465@gmail.com Contraseña: Dmer32deku | G8: =IF(H8>0,8,0) -> 0 | I8: 30 | J8: =+'HBO F'!$H8+'HBO F'!$I8 -> 30 | K8: ='HBO F'!$H8+'HBO F'!$I8-TODAY() -> -45566 | L8: =IF(K8<1,"VENCIDO","VIGENTE") -> VENCIDO
G9: =IF(H9>0,8,0) -> 0 | I9: 30 | J9: =+'HBO F'!$H9+'HBO F'!$I9 -> 30 | K9: ='HBO F'!$H9+'HBO F'!$I9-TODAY() -> -45566 | L9: =IF(K9<1,"VENCIDO","VIGENTE") -> VENCIDO
G10: =IF(H10>0,8,0) -> 0 | I10: 30 | J10: =+'HBO F'!$H10+'HBO F'!$I10 -> 30 | K10: ='HBO F'!$H10+'HBO F'!$I10-TODAY() -> -45566 | L10: =IF(K10<1,"VENCIDO","VIGENTE") -> VENCIDO
G11: =IF(H11>0,8,0) -> 0 | I11: 30 | J11: =+'HBO F'!$H11+'HBO F'!$I11 -> 30 | K11: ='HBO F'!$H11+'HBO F'!$I11-TODAY() -> -45566 | L11: =IF(K11<1,"VENCIDO","VIGENTE") -> VENCIDO
G12: =IF(H12>0,8,0) -> 0 | I12: 30 | J12: =+'HBO F'!$H12+'HBO F'!$I12 -> 30 | K12: ='HBO F'!$H12+'HBO F'!$I12-TODAY() -> -45566 | L12: =IF(K12<1,"VENCIDO","VIGENTE") -> VENCIDO
C13: PERFILES : | F13: =SUM(F8:F12) -> 0 | G13: =SUM(G8:G12) -> 0
B18: ALERTA DIAS | C18: Renovar
B19: =TODAY() -> 45596
B20: CUENTA | C20: NOMBRE | D20: CLAVE | E20: TELEFONO | F20: PIN PERFIL | G20: PRECIO | H20: FECHA DE INICIO | I20: DIAS | J20: FECHA DE VENCIMIENTO | K20: ALARMA | L20: ESTADO
B21: correo:filtroperu123+begrenzter@gmail.com contraseña_: campeonato99 | C21: Deereck92 | D21: campeonato99 | E21: 51 963 840 072 | F21: 9177 | G21: =IF(H21>0,5,0) -> 5 | H21: 45568 | I21: 30 | J21: =+'HBO F'!$H21+'HBO F'!$I21 -> 45598 | K21: ='HBO F'!$H21+'HBO F'!$I21-TODAY() -> 2 | L21: =IF(K21<1,"VENCIDO","VIGENTE") -> VIGENTE
C22: Remylag933 | E22: 51 926 665 678 | F22: 6333 | G22: =IF(H22>0,5,0) -> 5 | H22: 45565 | I22: 30 | J22: =+'HBO F'!$H22+'HBO F'!$I22 -> 45595 | K22: ='HBO F'!$H22+'HBO F'!$I22-TODAY() -> -1 | L22: =IF(K22<1,"VENCIDO","VIGENTE") -> VENCIDO
C23: Geraldine528 | E23: 51 946 579 911 | F23: 4288 | G23: =IF(H23>0,4,0) -> 4 | H23: 45543 | I23: 30 | J23: =+'HBO F'!$H23+'HBO F'!$I23 -> 45573 | K23: ='HBO F'!$H23+'HBO F'!$I23-TODAY() -> -23 | L23: =IF(K23<1,"VENCIDO","VIGENTE") -> VENCIDO
C24: Criss02 | E24: 51 946 579 911 | F24: 5534 | G24: =IF(H24>0,4,0) -> 4 | H24: 45536 | I24: 30 | J24: =+'HBO F'!$H24+'HBO F'!$I24 -> 45566 | K24: ='HBO F'!$H24+'HBO F'!$I24-TODAY() -> -30 | L24: =IF(K24<1,"VENCIDO","VIGENTE") -> VENCIDO
G25: =IF(H25>0,8,0) -> 0 | I25: 30 | J25: =+'HBO F'!$H25+'HBO F'!$I25 -> 30 | K25: ='HBO F'!$H25+'HBO F'!$I25-TODAY() -> -45566 | L25: =IF(K25<1,"VENCIDO","VIGENTE") -> VENCIDO
C26: PERFILES : | F26: =SUM(F21:F25) -> 25332 | G26: =SUM(G21:G25) -> 18
B31: ALERTA DIAS
B32: =TODAY() -> 45596
B33: CUENTA | C33: NOMBRE | D33: CLAVE | E33: TELEFONO | F33: PIN PERFIL | G33: PRECIO | H33: FECHA DE INICIO | I33: DIAS | J33: FECHA DE VENCIMIENTO | K33: ALARMA | L33: ESTADO
B34: Correo: lukcris961@gmail.com Contraseña: gerta54$ | G34: =IF(H34>0,8,0) -> 0 | I34: 30 | J34: =+'HBO F'!$H34+'HBO F'!$I34 -> 30 | K34: ='HBO F'!$H34+'HBO F'!$I34-TODAY() -> -45566 | L34: =IF(K34<1,"VENCIDO","VIGENTE") -> VENCIDO
G35: =IF(H35>0,8,0) -> 0 | I35: 30 | J35: =+'HBO F'!$H35+'HBO F'!$I35 -> 30 | K35: ='HBO F'!$H35+'HBO F'!$I35-TODAY() -> -45566 | L35: =IF(K35<1,"VENCIDO","VIGENTE") -> VENCIDO
G36: =IF(H36>0,8,0) -> 0 | I36: 60 | J36: =+'HBO F'!$H36+'HBO F'!$I36 -> 60 | K36: ='HBO F'!$H36+'HBO F'!$I36-TODAY() -> -45536 | L36: =IF(K36<1,"VENCIDO","VIGENTE") -> VENCIDO
G37: =IF(H37>0,8,0) -> 0 | I37: 180 | J37: =+'HBO F'!$H37+'HBO F'!$I37 -> 180 | K37: ='HBO F'!$H37+'HBO F'!$I37-TODAY() -> -45416 | L37: =IF(K37<1,"VENCIDO","VIGENTE") -> VENCIDO
G38: =IF(H38>0,8,0) -> 0 | I38: 30 | J38: =+'HBO F'!$H38+'HBO F'!$I38 -> 30 | K38: ='HBO F'!$H38+'HBO F'!$I38-TODAY() -> -45566 | L38: =IF(K38<1,"VENCIDO","VIGENTE") -> VENCIDO
C39: PERFILES : | F39: =SUM(F34:F38) -> 0 | G39: =SUM(G34:G38) -> 0
B44: ALERTA DIAS
